Workbook

Sheet 摘要
A1: Hugging Face 熱門模型資安適用性評分
A2: 結論 (依預設權重): 符合模型來源白名單的 4,289 個熱門模型中, 2,500 個通過6道排除條件, 其中 54 個評為「優先評估」. 前段以 AI 應用防護、個資偵測與資安語言模型為主; 一般用途模型以多語 embedding 與本地端語言模型分數最高.
A3: 範圍: 近六個月 (2026-04-25 至 2026-10-25) 下載量占 Hugging Face 全站 95% 的模型; 先依手冊 M3 章的模型來源白名單原則篩選. 資料來源: Hugging Face hub-stats 資料集 (cfahlgren1/hub-stats) 兩份快照. 評分規則見「評分方法」分頁.
A5: 篩選漏斗 | B5: 模型數 | C5: 占比 | F5: 說明
A6: 納入評估的熱門模型 | B6: =B7+B8 -> 4289 | C6: =B6/B6 -> 1 | F6: 近六個月下載量前 95% 且符合模型來源白名單
A7: 觸及至少一項排除條件 | B7: =COUNTA(排除清單!A2:A1790) -> 1789 | C7: =B7/B6 -> 0.41711355 | F7: 明細見「排除清單」分頁
A8: 通過篩選並評分 | B8: =COUNTA(資安適用排名!B2:B2501) -> 2500 | C8: =B8/B6 -> 0.58288645 | F8: 明細見「資安適用排名」分頁
A10: 排除條件 | B10: 觸及模型數 | C10: 占總數 | F10: 說明
A11: G1 移除護欄或不當用途 | B11: =COUNTIF(排除清單!$G$2:$G$1790,"*G1*") -> 66 | C11: =B11/$B$6 -> 0.015388202 | F11: 名稱含 uncensored、abliterated、heretic、offsec 或成人內容生成
A12: G2 測試用模型 | B12: =COUNTIF(排除清單!$G$2:$G$1790,"*G2*") -> 209 | C12: =B12/$B$6 -> 0.048729308 | F12: 名稱或帳號含 internal-testing、tiny-random 等
A13: G3 權重格式可執行程式碼 | B13: =COUNTIF(排除清單!$G$2:$G$1790,"*G3*") -> 909 | C13: =B13/$B$6 -> 0.21193751 | F13: 沒有 safetensors、GGUF 或 ONNX 權重, 只提供 pickle 等格式
A14: G4 需執行遠端程式碼 | B14: =COUNTIF(排除清單!$G$2:$G$1790,"*G4*") -> 277 | C14: =B14/$B$6 -> 0.064583819 | F14: 帶 custom_code 標籤, 載入時須開啟 trust_remote_code
A15: G5 授權不允許商用 | B15: =COUNTIF(排除清單!$G$2:$G$1790,"*G5*") -> 191 | C15: =B15/$B$6 -> 0.044532525 | F15: CC BY-NC 系列、Apple AMLR、研究專用授權
A16: G6 無防禦用途 | B16: =COUNTIF(排除清單!$G$2:$G$1790,"*G6*") -> 373 | C16: =B16/$B$6 -> 0.086966659 | F16: 生成影像、影音或語音的模型
A18: 註: 一個模型可能同時觸及多項條件, 各條件模型數加總會大於排除總數.
A20: 適用等級 | B20: 模型數 | C20: 占通過數 | D20: 門檻 | F20: 意義
A21: 優先評估 | B21: =COUNTIF(資安適用排名!$H$2:$H$2501,A21) -> 54 | C21: =B21/$B$8 -> 0.0216 | D21: =評分方法!$C$16 -> 80 | F21: 可直接列入 PoC 候選
A22: 列入候選 | B22: =COUNTIF(資安適用排名!$H$2:$H$2501,A22) -> 412 | C22: =B22/$B$8 -> 0.1648 | D22: =評分方法!$C$17 -> 70 | F22: 符合多數條件, 需比較同類模型後再選
A23: 特定情境 | B23: =COUNTIF(資安適用排名!$H$2:$H$2501,A23) -> 993 | C23: =B23/$B$8 -> 0.3972 | D23: =評分方法!$C$18 -> 60 | F23: 只在特定使用情境或資料條件下適用
A24: 不建議 | B24: =COUNTIF(資安適用排名!$H$2:$H$2501,A24) -> 1041 | C24: =B24/$B$8 -> 0.4164 | D24: =評分方法!$C$19 -> 0 | F24: 條件不足, 不建議投入評估資源
A26: 資安用途類別 | B26: 模型數 | C26: 最高分 | D26: 平均分 | E26: 優先評估數 | F26: 代表用途
A27: AI 應用防護 | B27: =COUNTIF(資安適用排名!$D$2:$D$2501,A27) -> 19 | C27: =_xlfn.MAXIFS(資安適用排名!$G$2:$G$2501,資安適用排名!$D$2:$D$2501,A27) -> 93.848 | D27: =AVERAGEIF(資安適用排名!$D$2:$D$2501,A27,資安適用排名!$G$2:$G$2501) -> 77.945895 | E27: =COUNTIFS(資安適用排名!$D$2:$D$2501,A27,資安適用排名!$H$2:$H$2501,"優先評估") -> 9 | F27: AI 應用的提示注入、越獄與有害內容偵測
A28: 個資偵測與去識別化 | B28: =COUNTIF(資安適用排名!$D$2:$D$2501,A28) -> 15 | C28: =_xlfn.MAXIFS(資安適用排名!$G$2:$G$2501,資安適用排名!$D$2:$D$2501,A28) -> 91.272 | D28: =AVERAGEIF(資安適用排名!$D$2:$D$2501,A28,資安適用排名!$G$2:$G$2501) -> 77.229867 | E28: =COUNTIFS(資安適用排名!$D$2:$D$2501,A28,資安適用排名!$H$2:$H$2501,"優先評估") -> 5 | F28: 個資偵測與遮蔽
A29: 威脅情資與資安語言 | B29: =COUNTIF(資安適用排名!$D$2:$D$2501,A29) -> 3 | C29: =_xlfn.MAXIFS(資安適用排名!$G$2:$G$2501,資安適用排名!$D$2:$D$2501,A29) -> 88.632 | D29: =AVERAGEIF(資安適用排名!$D$2:$D$2501,A29,資安適用排名!$G$2:$G$2501) -> 79.619333 | E29: =COUNTIFS(資安適用排名!$D$2:$D$2501,A29,資安適用排名!$H$2:$H$2501,"優先評估") -> 2 | F29: 以資安語料訓練, 適合情資檢索與實體擷取
A30: 深偽與生成內容偵測 | B30: =COUNTIF(資安適用排名!$D$2:$D$2501,A30) -> 4 | C30: =_xlfn.MAXIFS(資安適用排名!$G$2:$G$2501,資安適用排名!$D$2:$D$2501,A30) -> 86.384 | D30: =AVERAGEIF(資安適用排名!$D$2:$D$2501,A30,資安適用排名!$G$2:$G$2501) -> 72.4795 | E30: =COUNTIFS(資安適用排名!$D$2:$D$2501,A30,資安適用排名!$H$2:$H$2501,"優先評估") -> 1 | F30: 偵測 AI 生成的圖片或文字, 輔助詐騙與社交工程防範
A31: 檢索與情資關聯 | B31: =COUNTIF(資安適用排名!$D$2:$D$2501,A31) -> 270 | C31: =_xlfn.MAXIFS(資安適用排名!$G$2:$G$2501,資安適用排名!$D$2:$D$2501,A31) -> 85.988 | D31: =AVERAGEIF(資安適用排名!$D$2:$D$2501,A31,資安適用排名!$G$2:$G$2501) -> 67.009985 | E31: =COUNTIFS(資安適用排名!$D$2:$D$2501,A31,資安適用排名!$H$2:$H$2501,"優先評估") -> 25 | F31: 威脅情資語意搜尋、相似告警比對、事件知識庫 RAG
A32: 分析與報告生成 | B32: =COUNTIF(資安適用排名!$D$2:$D$2501,A32) -> 981 | C32: =_xlfn.MAXIFS(資安適用排名!$G$2:$G$2501,資安適用排名!$D$2:$D$2501,A32) -> 82.322 | D32: =AVERAGEIF(資安適用排名!$D$2:$D$2501,A32,資安適用排名!$G$2:$G$2501) -> 64.069498 | E32: =COUNTIFS(資安適用排名!$D$2:$D$2501,A32,資安適用排名!$H$2:$H$2501,"優先評估") -> 6 | F32: 告警分診摘要、ATT&CK 對映、事件報告初稿 (需人工確認)
A33: 實體擷取與去識別化 | B33: =COUNTIF(資安適用排名!$D$2:$D$2501,A33) -> 357 | C33: =_xlfn.MAXIFS(資安適用排名!$G$2:$G$2501,資安適用排名!$D$2:$D$2501,A33) -> 82.32 | D33: =AVERAGEIF(資安適用排名!$D$2:$D$2501,A33,資安適用排名!$G$2:$G$2501) -> 63.647249 | E33: =COUNTIFS(資安適用排名!$D$2:$D$2501,A33,資安適用排名!$H$2:$H$2501,"優先評估") -> 3 | F33: 從報告擷取 IOC 與實體, log 與工單個資遮蔽
A34: AI 紅隊評估 | B34: =COUNTIF(資安適用排名!$D$2:$D$2501,A34) -> 7 | C34: =_xlfn.MAXIFS(資安適用排名!$G$2:$G$2501,資安適用排名!$D$2:$D$2501,A34) -> 82.04 | D34: =AVERAGEIF(資安適用排名!$D$2:$D$2501,A34,資安適用排名!$G$2:$G$2501) -> 70.856571 | E34: =COUNTIFS(資安適用排名!$D$2:$D$2501,A34,資安適用排名!$H$2:$H$2501,"優先評估") -> 1 | F34: LLM 弱點掃描工具 garak 的偵測元件
A35: 日誌異常偵測 | B35: =COUNTIF(資安適用排名!$D$2:$D$2501,A35) -> 1 | C35: =_xlfn.MAXIFS(資安適用排名!$G$2:$G$2501,資安適用排名!$D$2:$D$2501,A35) -> 81.654 | D35: =AVERAGEIF(資安適用排名!$D$2:$D$2501,A35,資安適用排名!$G$2:$G$2501) -> 81.654 | E35: =COUNTIFS(資安適用排名!$D$2:$D$2501,A35,資安適用排名!$H$2:$H$2501,"優先評估") -> 1 | F35: 日誌序列異常分類
A36: 釣魚與垃圾訊息偵測 | B36: =COUNTIF(資安適用排名!$D$2:$D$2501,A36) -> 3 | C36: =_xlfn.MAXIFS(資安適用排名!$G$2:$G$2501,資安適用排名!$D$2:$D$2501,A36) -> 80.734 | D36: =AVERAGEIF(資安適用排名!$D$2:$D$2501,A36,資安適用排名!$G$2:$G$2501) -> 72.171333 | E36: =COUNTIFS(資安適用排名!$D$2:$D$2501,A36,資安適用排名!$H$2:$H$2501,"優先評估") -> 1 | F36: 釣魚郵件、垃圾訊息或惡意網址分類
A37: 分類與偵測 | B37: =COUNTIF(資安適用排名!$D$2:$D$2501,A37) -> 88 | C37: =_xlfn.MAXIFS(資安適用排名!$G$2:$G$2501,資安適用排名!$D$2:$D$2501,A37) -> 78.266 | D37: =AVERAGEIF(資安適用排名!$D$2:$D$2501,A37,資安適用排名!$G$2:$G$2501) -> 57.461864 | E37: =COUNTIFS(資安適用排名!$D$2:$D$2501,A37,資安適用排名!$H$2:$H$2501,"優先評估") -> 0 | F37: 告警分類、釣魚郵件判斷、日誌事件分類 (需以資安資料微調)
A38: 時序異常偵測 | B38: =COUNTIF(資安適用排名!$D$2:$D$2501,A38) -> 53 | C38: =_xlfn.MAXIFS(資安適用排名!$G$2:$G$2501,資安適用排名!$D$2:$D$2501,A38) -> 77.48 | D38: =AVERAGEIF(資安適用排名!$D$2:$D$2501,A38,資安適用排名!$G$2:$G$2501) -> 67.840981 | E38: =COUNTIFS(資安適用排名!$D$2:$D$2501,A38,資安適用排名!$H$2:$H$2501,"優先評估") -> 0 | F38: OT 製程數據、流量與登入次數的時序異常偵測
... A44: 其他 | B44: =COUNTIF(資安適用排名!$D$2:$D$2501,A44) -> 90 | C44: =_xlfn.MAXIFS(資安適用排名!$G$2:$G$2501,資安適用排名!$D$2:$D$2501,A44) -> 61.504 | D44: =AVERAGEIF(資安適用排名!$D$2:$D$2501,A44,資安適用排名!$G$2:$G$2501) -> 43.172311 | E44: =COUNTIFS(資安適用排名!$D$2:$D$2501,A44,資安適用排名!$H$2:$H$2501,"優先評估") -> 0 | F44: 用途有限
A46: 總排名前 20 | B46: 總分 | C46: 適用等級 | F46: 模型 ID
A47: 1 | B47: =INDEX(資安適用排名!$G$2:$G$2501,MATCH(A47,資安適用排名!$A$2:$A$2501,0)) -> 93.848 | C47: =INDEX(資安適用排名!$H$2:$H$2501,MATCH(A47,資安適用排名!$A$2:$A$2501,0)) -> 優先評估 | F47: =INDEX(資安適用排名!$B$2:$B$2501,MATCH(A47,資安適用排名!$A$2:$A$2501,0)) -> protectai/deberta-v3-base-prompt-injection-v2
A48: 2 | B48: =INDEX(資安適用排名!$G$2:$G$2501,MATCH(A48,資安適用排名!$A$2:$A$2501,0)) -> 91.272 | C48: =INDEX(資安適用排名!$H$2:$H$2501,MATCH(A48,資安適用排名!$A$2:$A$2501,0)) -> 優先評估 | F48: =INDEX(資安適用排名!$B$2:$B$2501,MATCH(A48,資安適用排名!$A$2:$A$2501,0)) -> gravitee-io/bert-small-pii-detection
A49: 3 | B49: =INDEX(資安適用排名!$G$2:$G$2501,MATCH(A49,資安適用排名!$A$2:$A$2501,0)) -> 90.486 | C49: =INDEX(資安適用排名!$H$2:$H$2501,MATCH(A49,資安適用排名!$A$2:$A$2501,0)) -> 優先評估 | F49: =INDEX(資安適用排名!$B$2:$B$2501,MATCH(A49,資安適用排名!$A$2:$A$2501,0)) -> openai/privacy-filter
A50: 4 | B50: =INDEX(資安適用排名!$G$2:$G$2501,MATCH(A50,資安適用排名!$A$2:$A$2501,0)) -> 89.792 | C50: =INDEX(資安適用排名!$H$2:$H$2501,MATCH(A50,資安適用排名!$A$2:$A$2501,0)) -> 優先評估 | F50: =INDEX(資安適用排名!$B$2:$B$2501,MATCH(A50,資安適用排名!$A$2:$A$2501,0)) -> meta-llama/Prompt-Guard-86M
A51: 5 | B51: =INDEX(資安適用排名!$G$2:$G$2501,MATCH(A51,資安適用排名!$A$2:$A$2501,0)) -> 89.14 | C51: =INDEX(資安適用排名!$H$2:$H$2501,MATCH(A51,資安適用排名!$A$2:$A$2501,0)) -> 優先評估 | F51: =INDEX(資安適用排名!$B$2:$B$2501,MATCH(A51,資安適用排名!$A$2:$A$2501,0)) -> fastino/gliner2-privacy-filter-PII-multi
...

Sheet 評分方法
A1: 資安適用性評分方法
A2: 使用方式: 「權重」與「等級門檻」兩欄可直接修改, 其他分頁的分數、等級與排名會自動重算. 修改後若要調整列的順序, 可在「資安適用排名」分頁依「排名」欄重新排序.
A4: 代號 | B4: 評分面向 | C4: 權重 (可修改) | D4: 計分方式 (原始比率 0 至 1) | E4: 依據
A5: A | B5: 任務適配 | C5: 30 | D5: 依任務類型給基礎比率 (見下方對照表); 專精領域與資安無關 (醫療、情緒分析等) 乘 0.4; 只支援特定外語乘 0.6 | E5: 任務能否直接用於偵測、分類、擷取、檢索或分析 [推論]
A6: B | B6: 資安專精 | C6: 10 | D6: 以資安資料或資安任務訓練: AI 應用防護、情資、釣魚、個資、日誌、紅隊 = 1.0; 深偽與生成內容偵測 = 0.7; 內容安全審查 = 0.5; 一般模型 = 0 | E6: 依模型名稱比對資安用途關鍵字, 並人工排除誤判
A7: C | B7: 來源可信度 | C7: 15 | D7: 原始開發組織 = 1.0; 知名社群或重新封裝者 = 0.67; 其他帳號 = 0.33 | E7: 依帳號名單分級 (見下方名單) [推論]
A8: D | B8: 部署可行性 | C8: 15 | D8: 參數量 10 億以下 = 1.0; 100 億以下 = 0.87; 350 億以下 = 0.6; 1,000 億以下 = 0.33; 以上 = 0.13; 未標示 = 0.47 | E8: 能否在內網以一般 GPU 或 CPU 部署
A9: E | B9: 授權友善度 | C9: 10 | D9: Apache 2.0、MIT、BSD、CC BY = 1.0; CC BY-SA = 0.8; OpenRAIL = 0.7; Llama、Gemma 等自訂授權 = 0.6; GPL 類 = 0.5; 未標示 = 0.2 | E9: 模型頁面授權標籤; 非商用授權已列為排除條件
A10: F | B10: 採用度 | C10: 10 | D10: 近六個月下載數在通過篩選模型中的百分位 | E10: 兩份全站快照的累計下載數相減
A11: G | B11: 維護活躍度 | C11: 5 | D11: 最後更新距 2026-10-25 在 6 個月內 = 1.0; 1 年內 = 0.8; 2 年內 = 0.5; 更久 = 0.2 | E11: 模型頁面最後更新日期
A12: H | B12: 中文支援 | C12: 5 | D12: 標示支援中文或多語 = 1.0; 未標示語言的大型語言模型 = 0.6; 未標示語言 = 0.3; 標示語言但不含中文 = 0 | E12: 模型頁面語言標籤 [推論: 大型語言模型通常支援中文, 但未經測試]
B13: 合計 | C13: =SUM(C5:C12) -> 100 | D13: 總分 = 各面向原始比率 × 權重後加總, 滿分為權重合計
B15: 適用等級 | C15: 門檻 (可修改) | D15: 意義
B16: 優先評估 | C16: 80 | D16: 可直接列入 PoC 候選
B17: 列入候選 | C17: 70 | D17: 符合多數條件, 需比較同類模型後再選
B18: 特定情境 | C18: 60 | D18: 只在特定使用情境或資料條件下適用
B19: 不建議 | C19: 0 | D19: 條件不足, 不建議投入評估資源
A21: 代號 | B21: 排除條件 | D21: 說明 | E21: 理由
A22: G1 | B22: 移除護欄或不當用途 | D22: 名稱含 uncensored、abliterated、heretic、offsec 或成人內容生成 | E22: 不適合放進防禦流程, 且有濫用疑慮
A23: G2 | B23: 測試用模型 | D23: 名稱或帳號含 internal-testing、tiny-random 等 | E23: 供框架測試, 非正式用途
A24: G3 | B24: 權重格式可執行程式碼 | D24: 沒有 safetensors、GGUF 或 ONNX 權重, 只提供 pickle 等格式 | E24: pickle 載入時可能執行任意程式碼
A25: G4 | B25: 需執行遠端程式碼 | D25: 帶 custom_code 標籤, 載入時須開啟 trust_remote_code | E25: 等於執行模型倉庫中的 Python 程式
A26: G5 | B26: 授權不允許商用 | D26: CC BY-NC 系列、Apple AMLR、研究專用授權 | E26: 無法用於商業服務或對外提供
A27: G6 | B27: 無防禦用途 | D27: 生成影像、影音或語音的模型 | E27: 與偵測和防禦無關
B30: 任務類型 | C30: 任務適配比率 | D30: 對應資安用途類別
B31: text-classification | C31: 1 | D31: 分類與偵測
B32: token-classification | C32: 0.95 | D32: 實體擷取與去識別化
B33: zero-shot-classification | C33: 0.9 | D33: 分類與偵測
B34: sentence-similarity | C34: 0.9 | D34: 檢索與情資關聯
B35: feature-extraction | C35: 0.9 | D35: 檢索與情資關聯
B36: text-ranking | C36: 0.9 | D36: 檢索與情資關聯
B37: text-generation | C37: 0.85 | D37: 分析與報告生成
B38: image-text-to-text | C38: 0.85 | D38: 分析與報告生成
B39: any-to-any | C39: 0.8 | D39: 分析與報告生成
B40: time-series-forecasting | C40: 0.7 | D40: 時序異常偵測
B41: question-answering | C41: 0.6 | D41: 分析與報告生成
B42: summarization | C42: 0.6 | D42: 分析與報告生成
... B83: robotics | C83: 0 | D83: 無防禦用途 (G7)
B85: 來源分級 | D85: 帳號名單
B86: 原始開發組織 | D86: ai-safety-institute, ai21labs, allenai, amazon, amd, answerdotai, apple, argmaxinc, autogluon, aws, babelscape, bigcode, bigscience, black-forest-labs, bsc-lm, cardiffnlp, cisco-ai, cohere, cohereforai, coherelabs, colbert-ir, comfy-org, compvis, coqui, cross-encoder, databricks, datalab-to, deepset, distilbert, docling-project, eleutherai, facebook, facebookai, fastino, fdtn-ai, flair, garak-llm, google, google-bert, google-research, google-t5, gravitee-io, guardrailsai, helsinki-nlp, hexgrad, huggingface, huggingfacem4, huggingfacetb, ibm, ibm-granite, ibm-research, intel, intfloat, jhu-clsp, jinaai, kyutai, laion, lightonai, liquidai, llava-hf, meta-llama, microsoft, microsoft-research, mistralai, mixedbread-ai, mosaicml, nomic-ai, nreimers, nvidia, nvidia-community, openai, openai-community, openmmlab, projecte-aina, protectai, pyannote, qdrant, runwayml, salesforce, sarvamai, sentence-transformers, servicenow-ai, snowflake, speechbrain, stabilityai, stanfordaimi, stanfordnlp, systran, tiiuae, timm, ultralytics, unbabel, vectara
...

Sheet 資安適用排名
A1: 排名 | B1: 模型 ID | C1: 作者 | D1: 資安用途類別 | E1: 建議用途 | F1: 資安專精領域 | G1: 總分 | H1: 適用等級 | I1: 任務適配 | J1: 資安專精 | K1: 來源可信度 | L1: 部署可行性 | M1: 授權友善度 | N1: 採用度 | O1: 維護活躍度 | P1: 中文支援 | Q1: 近六個月下載數 | R1: 參數量 | S1: 參數級距 | T1: 授權 | U1: 授權類型 | V1: 權重格式 | W1: 來源分級 | X1: 中文支援情形 | Y1: Base model | Z1: 衍生關係 | AA1: 任務類型 | AB1: 任務類型來源 | AC1: 備註 | AD1: 模型頁面 | AE1: A 比率 | AF1: B 比率 | AG1: C 比率 | AH1: D 比率 | AI1: E 比率 | AJ1: F 比率 | AK1: G 比率 | AL1: H 比率 | AM1: 類別內排名 | AN1: 查詢鍵
A2: =RANK(G2,$G$2:$G$2501)+COUNTIF($G$2:G2,G2)-1 -> 1 | B2: protectai/deberta-v3-base-prompt-injection-v2 | C2: protectai | D2: AI 應用防護 | E2: AI 應用的提示注入、越獄與有害內容偵測 | F2: AI 應用防護 | G2: =ROUND(SUM(I2:P2),3) -> 93.848 | H2: =IF(G2>=評分方法!$C$16,"優先評估",IF(G2>=評分方法!$C$17,"列入候選",IF(G2>=評分方法!$C$18,"特定情境","不建議"))) -> 優先評估 | I2: =AE2*評分方法!$C$5 -> 30 | J2: =AF2*評分方法!$C$6 -> 10 | K2: =AG2*評分方法!$C$7 -> 15 | L2: =AH2*評分方法!$C$8 -> 15 | M2: =AI2*評分方法!$C$9 -> 10 | N2: =AJ2*評分方法!$C$10 -> 8.848 | O2: =AK2*評分方法!$C$11 -> 5 | P2: =AL2*評分方法!$C$12 -> 0 | Q2: 3175433 | R2: 184423682 | S2: 10 億以下 | T2: apache-2.0 | U2: 寬鬆授權 | V2: safetensors;onnx | W2: 原始開發組織 | X2: 未標示中文 | Y2: microsoft/deberta-v3-base | Z2: quantized | AA2: text-classification | AB2: 作者標示 | AC2: 量化版本 | AD2: https://huggingface.co/protectai/deberta-v3-base-prompt-injection-v2 | AE2: 1 | AF2: 1 | AG2: 1 | AH2: 1 | AI2: 1 | AJ2: 0.8848 | AK2: 1 | AL2: 0 | AM2: =COUNTIFS($D$2:$D$2501,D2,$G$2:$G$2501,">"&G2)+COUNTIFS($D$2:D2,D2,$G$2:G2,G2) -> 1 | AN2: =D2&"|"&AM2 -> AI 應用防護|1
A3: =RANK(G3,$G$2:$G$2501)+COUNTIF($G$2:G3,G3)-1 -> 2 | B3: gravitee-io/bert-small-pii-detection | C3: gravitee-io | D3: 個資偵測與去識別化 | E3: 個資偵測與遮蔽 | F3: 個資偵測與去識別化 | G3: =ROUND(SUM(I3:P3),3) -> 91.272 | H3: =IF(G3>=評分方法!$C$16,"優先評估",IF(G3>=評分方法!$C$17,"列入候選",IF(G3>=評分方法!$C$18,"特定情境","不建議"))) -> 優先評估 | I3: =AE3*評分方法!$C$5 -> 28.5 | J3: =AF3*評分方法!$C$6 -> 10 | K3: =AG3*評分方法!$C$7 -> 15 | L3: =AH3*評分方法!$C$8 -> 15 | M3: =AI3*評分方法!$C$9 -> 10 | N3: =AJ3*評分方法!$C$10 -> 7.772 | O3: =AK3*評分方法!$C$11 -> 5 | P3: =AL3*評分方法!$C$12 -> 0 | Q3: 1349477 | R3: 28527155 | S3: 10 億以下 | T3: apache-2.0 | U3: 寬鬆授權 | V3: safetensors;onnx | W3: 原始開發組織 | X3: 未標示中文 | Y3: prajjwal1/bert-small | Z3: quantized | AA3: token-classification | AB3: 作者標示 | AC3: 量化版本 | AD3: https://huggingface.co/gravitee-io/bert-small-pii-detection | AE3: 0.95 | AF3: 1 | AG3: 1 | AH3: 1 | AI3: 1 | AJ3: 0.7772 | AK3: 1 | AL3: 0 | AM3: =COUNTIFS($D$2:$D$2501,D3,$G$2:$G$2501,">"&G3)+COUNTIFS($D$2:D3,D3,$G$2:G3,G3) -> 1 | AN3: =D3&"|"&AM3 -> 個資偵測與去識別化|1
A4: =RANK(G4,$G$2:$G$2501)+COUNTIF($G$2:G4,G4)-1 -> 3 | B4: openai/privacy-filter | C4: openai | D4: 個資偵測與去識別化 | E4: 個資偵測與遮蔽 | F4: 個資偵測與去識別化 | G4: =ROUND(SUM(I4:P4),3) -> 90.486 | H4: =IF(G4>=評分方法!$C$16,"優先評估",IF(G4>=評分方法!$C$17,"列入候選",IF(G4>=評分方法!$C$18,"特定情境","不建議"))) -> 優先評估 | I4: =AE4*評分方法!$C$5 -> 28.5 | J4: =AF4*評分方法!$C$6 -> 10 | K4: =AG4*評分方法!$C$7 -> 15 | L4: =AH4*評分方法!$C$8 -> 13.05 | M4: =AI4*評分方法!$C$9 -> 10 | N4: =AJ4*評分方法!$C$10 -> 8.436 | O4: =AK4*評分方法!$C$11 -> 4 | P4: =AL4*評分方法!$C$12 -> 1.5 | Q4: 2096057 | R4: 1399486865 | S4: 10 億至 100 億 | T4: apache-2.0 | U4: 寬鬆授權 | V4: safetensors;onnx | W4: 原始開發組織 | X4: 未標示 | AA4: token-classification | AB4: 作者標示 | AD4: https://huggingface.co/openai/privacy-filter | AE4: 0.95 | AF4: 1 | AG4: 1 | AH4: 0.87 | AI4: 1 | AJ4: 0.8436 | AK4: 0.8 | AL4: 0.3 | AM4: =COUNTIFS($D$2:$D$2501,D4,$G$2:$G$2501,">"&G4)+COUNTIFS($D$2:D4,D4,$G$2:G4,G4) -> 2 | AN4: =D4&"|"&AM4 -> 個資偵測與去識別化|2
A5: =RANK(G5,$G$2:$G$2501)+COUNTIF($G$2:G5,G5)-1 -> 4 | B5: meta-llama/Prompt-Guard-86M | C5: meta-llama | D5: AI 應用防護 | E5: AI 應用的提示注入、越獄與有害內容偵測 | F5: AI 應用防護 | G5: =ROUND(SUM(I5:P5),3) -> 89.792 | H5: =IF(G5>=評分方法!$C$16,"優先評估",IF(G5>=評分方法!$C$17,"列入候選",IF(G5>=評分方法!$C$18,"特定情境","不建議"))) -> 優先評估 | I5: =AE5*評分方法!$C$5 -> 30 | J5: =AF5*評分方法!$C$6 -> 10 | K5: =AG5*評分方法!$C$7 -> 15 | L5: =AH5*評分方法!$C$8 -> 15 | M5: =AI5*評分方法!$C$9 -> 6 | N5: =AJ5*評分方法!$C$10 -> 9.792 | O5: =AK5*評分方法!$C$11 -> 4 | P5: =AL5*評分方法!$C$12 -> 0 | Q5: 19784811 | R5: 278811651 | S5: 10 億以下 | T5: llama3.1 | U5: 自訂授權, 需法務審查 | V5: safetensors | W5: 原始開發組織 | X5: 未標示中文 | AA5: text-classification | AB5: 作者標示 | AC5: 授權需確認 | AD5: https://huggingface.co/meta-llama/Prompt-Guard-86M | AE5: 1 | AF5: 1 | AG5: 1 | AH5: 1 | AI5: 0.6 | AJ5: 0.9792 | AK5: 0.8 | AL5: 0 | AM5: =COUNTIFS($D$2:$D$2501,D5,$G$2:$G$2501,">"&G5)+COUNTIFS($D$2:D5,D5,$G$2:G5,G5) -> 2 | AN5: =D5&"|"&AM5 -> AI 應用防護|2
A6: =RANK(G6,$G$2:$G$2501)+COUNTIF($G$2:G6,G6)-1 -> 5 | B6: fastino/gliner2-privacy-filter-PII-multi | C6: fastino | D6: 個資偵測與去識別化 | E6: 個資偵測與遮蔽 | F6: 個資偵測與去識別化 | G6: =ROUND(SUM(I6:P6),3) -> 89.14 | H6: =IF(G6>=評分方法!$C$16,"優先評估",IF(G6>=評分方法!$C$17,"列入候選",IF(G6>=評分方法!$C$18,"特定情境","不建議"))) -> 優先評估 | I6: =AE6*評分方法!$C$5 -> 28.5 | J6: =AF6*評分方法!$C$6 -> 10 | K6: =AG6*評分方法!$C$7 -> 15 | L6: =AH6*評分方法!$C$8 -> 15 | M6: =AI6*評分方法!$C$9 -> 10 | N6: =AJ6*評分方法!$C$10 -> 5.64 | O6: =AK6*評分方法!$C$11 -> 5 | P6: =AL6*評分方法!$C$12 -> 0 | Q6: 584868 | R6: 307098645 | S6: 10 億以下 | T6: apache-2.0 | U6: 寬鬆授權 | V6: safetensors | W6: 原始開發組織 | X6: 未標示中文 | AA6: token-classification | AB6: 作者標示 | AD6: https://huggingface.co/fastino/gliner2-privacy-filter-PII-multi | AE6: 0.95 | AF6: 1 | AG6: 1 | AH6: 1 | AI6: 1 | AJ6: 0.564 | AK6: 1 | AL6: 0 | AM6: =COUNTIFS($D$2:$D$2501,D6,$G$2:$G$2501,">"&G6)+COUNTIFS($D$2:D6,D6,$G$2:G6,G6) -> 3 | AN6: =D6&"|"&AM6 -> 個資偵測與去識別化|3
A7: =RANK(G7,$G$2:$G$2501)+COUNTIF($G$2:G7,G7)-1 -> 6 | B7: cisco-ai/SecureBERT2.0-biencoder | C7: cisco-ai | D7: 威脅情資與資安語言 | E7: 以資安語料訓練, 適合情資檢索與實體擷取 | F7: 威脅情資與資安語言 | G7: =ROUND(SUM(I7:P7),3) -> 88.632 | H7: =IF(G7>=評分方法!$C$16,"優先評估",IF(G7>=評分方法!$C$17,"列入候選",IF(G7>=評分方法!$C$18,"特定情境","不建議"))) -> 優先評估 | I7: =AE7*評分方法!$C$5 -> 27 | J7: =AF7*評分方法!$C$6 -> 10 | K7: =AG7*評分方法!$C$7 -> 15 | L7: =AH7*評分方法!$C$8 -> 15 | M7: =AI7*評分方法!$C$9 -> 10 | N7: =AJ7*評分方法!$C$10 -> 6.632 | O7: =AK7*評分方法!$C$11 -> 5 | P7: =AL7*評分方法!$C$12 -> 0 | Q7: 786528 | R7: 149014272 | S7: 10 億以下 | T7: apache-2.0 | U7: 寬鬆授權 | V7: safetensors | W7: 原始開發組織 | X7: 未標示中文 | Y7: cisco-ai/SecureBERT2.0-base | Z7: finetune | AA7: sentence-similarity | AB7: 作者標示 | AD7: https://huggingface.co/cisco-ai/SecureBERT2.0-biencoder | AE7: 0.9 | AF7: 1 | AG7: 1 | AH7: 1 | AI7: 1 | AJ7: 0.6632 | AK7: 1 | AL7: 0 | AM7: =COUNTIFS($D$2:$D$2501,D7,$G$2:$G$2501,">"&G7)+COUNTIFS($D$2:D7,D7,$G$2:G7,G7) -> 1 | AN7: =D7&"|"&AM7 -> 威脅情資與資安語言|1
A8: =RANK(G8,$G$2:$G$2501)+COUNTIF($G$2:G8,G8)-1 -> 7 | B8: protectai/deberta-v3-base-prompt-injection | C8: protectai | D8: AI 應用防護 | E8: AI 應用的提示注入、越獄與有害內容偵測 | F8: AI 應用防護 | G8: =ROUND(SUM(I8:P8),3) -> 88.328 | H8: =IF(G8>=評分方法!$C$16,"優先評估",IF(G8>=評分方法!$C$17,"列入候選",IF(G8>=評分方法!$C$18,"特定情境","不建議"))) -> 優先評估 | I8: =AE8*評分方法!$C$5 -> 30 | J8: =AF8*評分方法!$C$6 -> 10 | K8: =AG8*評分方法!$C$7 -> 15 | L8: =AH8*評分方法!$C$8 -> 15 | M8: =AI8*評分方法!$C$9 -> 10 | N8: =AJ8*評分方法!$C$10 -> 3.328 | O8: =AK8*評分方法!$C$11 -> 5 | P8: =AL8*評分方法!$C$12 -> 0 | Q8: 330365 | R8: 184423682 | S8: 10 億以下 | T8: apache-2.0 | U8: 寬鬆授權 | V8: safetensors;onnx | W8: 原始開發組織 | X8: 未標示中文 | Y8: microsoft/deberta-v3-base | Z8: quantized | AA8: text-classification | AB8: 作者標示 | AC8: 量化版本 | AD8: https://huggingface.co/protectai/deberta-v3-base-prompt-injection | AE8: 1 | AF8: 1 | AG8: 1 | AH8: 1 | AI8: 1 | AJ8: 0.3328 | AK8: 1 | AL8: 0 | AM8: =COUNTIFS($D$2:$D$2501,D8,$G$2:$G$2501,">"&G8)+COUNTIFS($D$2:D8,D8,$G$2:G8,G8) -> 3 | AN8: =D8&"|"&AM8 -> AI 應用防護|3
A9: =RANK(G9,$G$2:$G$2501)+COUNTIF($G$2:G9,G9)-1 -> 8 | B9: cisco-ai/SecureBERT2.0-cross_encoder | C9: cisco-ai | D9: 威脅情資與資安語言 | E9: 以資安語料訓練, 適合情資檢索與實體擷取 | F9: 威脅情資與資安語言 | G9: =ROUND(SUM(I9:P9),3) -> 87.304 | H9: =IF(G9>=評分方法!$C$16,"優先評估",IF(G9>=評分方法!$C$17,"列入候選",IF(G9>=評分方法!$C$18,"特定情境","不建議"))) -> 優先評估 | I9: =AE9*評分方法!$C$5 -> 27 | J9: =AF9*評分方法!$C$6 -> 10 | K9: =AG9*評分方法!$C$7 -> 15 | L9: =AH9*評分方法!$C$8 -> 15 | M9: =AI9*評分方法!$C$9 -> 10 | N9: =AJ9*評分方法!$C$10 -> 6.304 | O9: =AK9*評分方法!$C$11 -> 4 | P9: =AL9*評分方法!$C$12 -> 0 | Q9: 696971 | R9: 149605633 | S9: 10 億以下 | T9: apache-2.0 | U9: 寬鬆授權 | V9: safetensors | W9: 原始開發組織 | X9: 未標示中文 | Y9: cisco-ai/SecureBERT2.0-base | Z9: finetune | AA9: sentence-similarity | AB9: 作者標示 | AD9: https://huggingface.co/cisco-ai/SecureBERT2.0-cross_encoder | AE9: 0.9 | AF9: 1 | AG9: 1 | AH9: 1 | AI9: 1 | AJ9: 0.6304 | AK9: 0.8 | AL9: 0 | AM9: =COUNTIFS($D$2:$D$2501,D9,$G$2:$G$2501,">"&G9)+COUNTIFS($D$2:D9,D9,$G$2:G9,G9) -> 2 | AN9: =D9&"|"&AM9 -> 威脅情資與資安語言|2
A10: =RANK(G10,$G$2:$G$2501)+COUNTIF($G$2:G10,G10)-1 -> 9 | B10: openai-community/roberta-base-openai-detector | C10: openai-community | D10: 深偽與生成內容偵測 | E10: 偵測 AI 生成的圖片或文字, 輔助詐騙與社交工程防範 | F10: 深偽與生成內容偵測 | G10: =ROUND(SUM(I10:P10),3) -> 86.384 | H10: =IF(G10>=評分方法!$C$16,"優先評估",IF(G10>=評分方法!$C$17,"列入候選",IF(G10>=評分方法!$C$18,"特定情境","不建議"))) -> 優先評估 | I10: =AE10*評分方法!$C$5 -> 30 | J10: =AF10*評分方法!$C$6 -> 7 | K10: =AG10*評分方法!$C$7 -> 15 | L10: =AH10*評分方法!$C$8 -> 15 | M10: =AI10*評分方法!$C$9 -> 10 | N10: =AJ10*評分方法!$C$10 -> 8.384 | O10: =AK10*評分方法!$C$11 -> 1 | P10: =AL10*評分方法!$C$12 -> 0 | Q10: 2038974 | R10: 125237762 | S10: 10 億以下 | T10: mit | U10: 寬鬆授權 | V10: safetensors;pytorch;tensorflow;flax | W10: 原始開發組織 | X10: 未標示中文 | AA10: text-classification | AB10: 作者標示 | AD10: https://huggingface.co/openai-community/roberta-base-openai-detector | AE10: 1 | AF10: 0.7 | AG10: 1 | AH10: 1 | AI10: 1 | AJ10: 0.8384 | AK10: 0.2 | AL10: 0 | AM10: =COUNTIFS($D$2:$D$2501,D10,$G$2:$G$2501,">"&G10)+COUNTIFS($D$2:D10,D10,$G$2:G10,G10) -> 1 | AN10: =D10&"|"&AM10 -> 深偽與生成內容偵測|1
A11: =RANK(G11,$G$2:$G$2501)+COUNTIF($G$2:G11,G11)-1 -> 10 | B11: sentence-transformers/paraphrase-multilingual-MiniLM-L12-v2 | C11: sentence-transformers | D11: 檢索與情資關聯 | E11: 威脅情資語意搜尋、相似告警比對、事件知識庫 RAG | G11: =ROUND(SUM(I11:P11),3) -> 85.988 | H11: =IF(G11>=評分方法!$C$16,"優先評估",IF(G11>=評分方法!$C$17,"列入候選",IF(G11>=評分方法!$C$18,"特定情境","不建議"))) -> 優先評估 | I11: =AE11*評分方法!$C$5 -> 27 | J11: =AF11*評分方法!$C$6 -> 0 | K11: =AG11*評分方法!$C$7 -> 15 | L11: =AH11*評分方法!$C$8 -> 15 | M11: =AI11*評分方法!$C$9 -> 10 | N11: =AJ11*評分方法!$C$10 -> 9.988 | O11: =AK11*評分方法!$C$11 -> 4 | P11: =AL11*評分方法!$C$12 -> 5 | Q11: 307740420 | R11: 117654272 | S11: 10 億以下 | T11: apache-2.0 | U11: 寬鬆授權 | V11: safetensors;pytorch;onnx;tensorflow | W11: 原始開發組織 | X11: 標示支援 | AA11: sentence-similarity | AB11: 作者標示 | AD11: https://huggingface.co/sentence-transformers/paraphrase-multilingual-MiniLM-L12-v2 | AE11: 0.9 | AF11: 0 | AG11: 1 | AH11: 1 | AI11: 1 | AJ11: 0.9988 | AK11: 0.8 | AL11: 1 | AM11: =COUNTIFS($D$2:$D$2501,D11,$G$2:$G$2501,">"&G11)+COUNTIFS($D$2:D11,D11,$G$2:G11,G11) -> 1 | AN11: =D11&"|"&AM11 -> 檢索與情資關聯|1
A12: =RANK(G12,$G$2:$G$2501)+COUNTIF($G$2:G12,G12)-1 -> 11 | B12: intfloat/multilingual-e5-small | C12: intfloat | D12: 檢索與情資關聯 | E12: 威脅情資語意搜尋、相似告警比對、事件知識庫 RAG | G12: =ROUND(SUM(I12:P12),3) -> 85.952 | H12: =IF(G12>=評分方法!$C$16,"優先評估",IF(G12>=評分方法!$C$17,"列入候選",IF(G12>=評分方法!$C$18,"特定情境","不建議"))) -> 優先評估 | I12: =AE12*評分方法!$C$5 -> 27 | J12: =AF12*評分方法!$C$6 -> 0 | K12: =AG12*評分方法!$C$7 -> 15 | L12: =AH12*評分方法!$C$8 -> 15 | M12: =AI12*評分方法!$C$9 -> 10 | N12: =AJ12*評分方法!$C$10 -> 9.952 | O12: =AK12*評分方法!$C$11 -> 4 | P12: =AL12*評分方法!$C$12 -> 5 | Q12: 71482081 | R12: 117654272 | S12: 10 億以下 | T12: mit | U12: 寬鬆授權 | V12: safetensors;pytorch;onnx | W12: 原始開發組織 | X12: 標示支援 | AA12: sentence-similarity | AB12: 作者標示 | AD12: https://huggingface.co/intfloat/multilingual-e5-small | AE12: 0.9 | AF12: 0 | AG12: 1 | AH12: 1 | AI12: 1 | AJ12: 0.9952 | AK12: 0.8 | AL12: 1 | AM12: =COUNTIFS($D$2:$D$2501,D12,$G$2:$G$2501,">"&G12)+COUNTIFS($D$2:D12,D12,$G$2:G12,G12) -> 2 | AN12: =D12&"|"&AM12 -> 檢索與情資關聯|2
A13: =RANK(G13,$G$2:$G$2501)+COUNTIF($G$2:G13,G13)-1 -> 12 | B13: intfloat/multilingual-e5-large | C13: intfloat | D13: 檢索與情資關聯 | E13: 威脅情資語意搜尋、相似告警比對、事件知識庫 RAG | G13: =ROUND(SUM(I13:P13),3) -> 85.912 | H13: =IF(G13>=評分方法!$C$16,"優先評估",IF(G13>=評分方法!$C$17,"列入候選",IF(G13>=評分方法!$C$18,"特定情境","不建議"))) -> 優先評估 | I13: =AE13*評分方法!$C$5 -> 27 | J13: =AF13*評分方法!$C$6 -> 0 | K13: =AG13*評分方法!$C$7 -> 15 | L13: =AH13*評分方法!$C$8 -> 15 | M13: =AI13*評分方法!$C$9 -> 10 | N13: =AJ13*評分方法!$C$10 -> 9.912 | O13: =AK13*評分方法!$C$11 -> 4 | P13: =AL13*評分方法!$C$12 -> 5 | Q13: 50955167 | R13: 559890946 | S13: 10 億以下 | T13: mit | U13: 寬鬆授權 | V13: safetensors;pytorch;onnx | W13: 原始開發組織 | X13: 標示支援 | AA13: feature-extraction | AB13: 作者標示 | AD13: https://huggingface.co/intfloat/multilingual-e5-large | AE13: 0.9 | AF13: 0 | AG13: 1 | AH13: 1 | AI13: 1 | AJ13: 0.9912 | AK13: 0.8 | AL13: 1 | AM13: =COUNTIFS($D$2:$D$2501,D13,$G$2:$G$2501,">"&G13)+COUNTIFS($D$2:D13,D13,$G$2:G13,G13) -> 3 | AN13: =D13&"|"&AM13 -> 檢索與情資關聯|3
A14: =RANK(G14,$G$2:$G$2501)+COUNTIF($G$2:G14,G14)-1 -> 13 | B14: intfloat/multilingual-e5-base | C14: intfloat | D14: 檢索與情資關聯 | E14: 威脅情資語意搜尋、相似告警比對、事件知識庫 RAG | G14: =ROUND(SUM(I14:P14),3) -> 85.884 | H14: =IF(G14>=評分方法!$C$16,"優先評估",IF(G14>=評分方法!$C$17,"列入候選",IF(G14>=評分方法!$C$18,"特定情境","不建議"))) -> 優先評估 | I14: =AE14*評分方法!$C$5 -> 27 | J14: =AF14*評分方法!$C$6 -> 0 | K14: =AG14*評分方法!$C$7 -> 15 | L14: =AH14*評分方法!$C$8 -> 15 | M14: =AI14*評分方法!$C$9 -> 10 | N14: =AJ14*評分方法!$C$10 -> 9.884 | O14: =AK14*評分方法!$C$11 -> 4 | P14: =AL14*評分方法!$C$12 -> 5 | Q14: 41221524 | R14: 278044162 | S14: 10 億以下 | T14: mit | U14: 寬鬆授權 | V14: safetensors;pytorch;onnx | W14: 原始開發組織 | X14: 標示支援 | AA14: sentence-similarity | AB14: 作者標示 | AD14: https://huggingface.co/intfloat/multilingual-e5-base | AE14: 0.9 | AF14: 0 | AG14: 1 | AH14: 1 | AI14: 1 | AJ14: 0.9884 | AK14: 0.8 | AL14: 1 | AM14: =COUNTIFS($D$2:$D$2501,D14,$G$2:$G$2501,">"&G14)+COUNTIFS($D$2:D14,D14,$G$2:G14,G14) -> 4 | AN14: =D14&"|"&AM14 -> 檢索與情資關聯|4
A15: =RANK(G15,$G$2:$G$2501)+COUNTIF($G$2:G15,G15)-1 -> 14 | B15: meta-llama/Llama-Prompt-Guard-2-86M | C15: meta-llama | D15: AI 應用防護 | E15: AI 應用的提示注入、越獄與有害內容偵測 | F15: AI 應用防護 | G15: =ROUND(SUM(I15:P15),3) -> 84.908 | H15: =IF(G15>=評分方法!$C$16,"優先評估",IF(G15>=評分方法!$C$17,"列入候選",IF(G15>=評分方法!$C$18,"特定情境","不建議"))) -> 優先評估 | I15: =AE15*評分方法!$C$5 -> 30 | J15: =AF15*評分方法!$C$6 -> 10 | K15: =AG15*評分方法!$C$7 -> 15 | L15: =AH15*評分方法!$C$8 -> 15 | M15: =AI15*評分方法!$C$9 -> 6 | N15: =AJ15*評分方法!$C$10 -> 6.408 | O15: =AK15*評分方法!$C$11 -> 2.5 | P15: =AL15*評分方法!$C$12 -> 0 | Q15: 726773 | R15: 278810882 | S15: 10 億以下 | T15: other | U15: 自訂授權, 需法務審查 | V15: safetensors | W15: 原始開發組織 | X15: 未標示中文 | AA15: text-classification | AB15: 作者標示 | AC15: 授權需確認 | AD15: https://huggingface.co/meta-llama/Llama-Prompt-Guard-2-86M | AE15: 1 | AF15: 1 | AG15: 1 | AH15: 1 | AI15: 0.6 | AJ15: 0.6408 | AK15: 0.5 | AL15: 0 | AM15: =COUNTIFS($D$2:$D$2501,D15,$G$2:$G$2501,">"&G15)+COUNTIFS($D$2:D15,D15,$G$2:G15,G15) -> 4 | AN15: =D15&"|"&AM15 -> AI 應用防護|4
A16: =RANK(G16,$G$2:$G$2501)+COUNTIF($G$2:G16,G16)-1 -> 15 | B16: sentence-transformers/paraphrase-multilingual-mpnet-base-v2 | C16: sentence-transformers | D16: 檢索與情資關聯 | E16: 威脅情資語意搜尋、相似告警比對、事件知識庫 RAG | G16: =ROUND(SUM(I16:P16),3) -> 84.42 | H16: =IF(G16>=評分方法!$C$16,"優先評估",IF(G16>=評分方法!$C$17,"列入候選",IF(G16>=評分方法!$C$18,"特定情境","不建議"))) -> 優先評估 | I16: =AE16*評分方法!$C$5 -> 27 | J16: =AF16*評分方法!$C$6 -> 0 | K16: =AG16*評分方法!$C$7 -> 15 | L16: =AH16*評分方法!$C$8 -> 15 | M16: =AI16*評分方法!$C$9 -> 10 | N16: =AJ16*評分方法!$C$10 -> 9.92 | O16: =AK16*評分方法!$C$11 -> 2.5 | P16: =AL16*評分方法!$C$12 -> 5 | Q16: 58178404 | R16: 278044162 | S16: 10 億以下 | T16: apache-2.0 | U16: 寬鬆授權 | V16: safetensors;pytorch;onnx;tensorflow | W16: 原始開發組織 | X16: 標示支援 | AA16: sentence-similarity | AB16: 作者標示 | AD16: https://huggingface.co/sentence-transformers/paraphrase-multilingual-mpnet-base-v2 | AE16: 0.9 | AF16: 0 | AG16: 1 | AH16: 1 | AI16: 1 | AJ16: 0.992 | AK16: 0.5 | AL16: 1 | AM16: =COUNTIFS($D$2:$D$2501,D16,$G$2:$G$2501,">"&G16)+COUNTIFS($D$2:D16,D16,$G$2:G16,G16) -> 5 | AN16: =D16&"|"&AM16 -> 檢索與情資關聯|5
A17: =RANK(G17,$G$2:$G$2501)+COUNTIF($G$2:G17,G17)-1 -> 16 | B17: ibm-granite/granite-embedding-97m-multilingual-r2 | C17: ibm-granite | D17: 檢索與情資關聯 | E17: 威脅情資語意搜尋、相似告警比對、事件知識庫 RAG | G17: =ROUND(SUM(I17:P17),3) -> 84.172 | H17: =IF(G17>=評分方法!$C$16,"優先評估",IF(G17>=評分方法!$C$17,"列入候選",IF(G17>=評分方法!$C$18,"特定情境","不建議"))) -> 優先評估 | I17: =AE17*評分方法!$C$5 -> 27 | J17: =AF17*評分方法!$C$6 -> 0 | K17: =AG17*評分方法!$C$7 -> 15 | L17: =AH17*評分方法!$C$8 -> 15 | M17: =AI17*評分方法!$C$9 -> 10 | N17: =AJ17*評分方法!$C$10 -> 7.172 | O17: =AK17*評分方法!$C$11 -> 5 | P17: =AL17*評分方法!$C$12 -> 5 | Q17: 985430 | R17: 97441152 | S17: 10 億以下 | T17: apache-2.0 | U17: 寬鬆授權 | V17: safetensors;pytorch;onnx | W17: 原始開發組織 | X17: 標示支援 | AA17: feature-extraction | AB17: 作者標示 | AD17: https://huggingface.co/ibm-granite/granite-embedding-97m-multilingual-r2 | AE17: 0.9 | AF17: 0 | AG17: 1 | AH17: 1 | AI17: 1 | AJ17: 0.7172 | AK17: 1 | AL17: 1 | AM17: =COUNTIFS($D$2:$D$2501,D17,$G$2:$G$2501,">"&G17)+COUNTIFS($D$2:D17,D17,$G$2:G17,G17) -> 6 | AN17: =D17&"|"&AM17 -> 檢索與情資關聯|6
A18: =RANK(G18,$G$2:$G$2501)+COUNTIF($G$2:G18,G18)-1 -> 17 | B18: cross-encoder/mmarco-mMiniLMv2-L12-H384-v1 | C18: cross-encoder | D18: 檢索與情資關聯 | E18: 威脅情資語意搜尋、相似告警比對、事件知識庫 RAG | G18: =ROUND(SUM(I18:P18),3) -> 84.148 | H18: =IF(G18>=評分方法!$C$16,"優先評估",IF(G18>=評分方法!$C$17,"列入候選",IF(G18>=評分方法!$C$18,"特定情境","不建議"))) -> 優先評估 | I18: =AE18*評分方法!$C$5 -> 27 | J18: =AF18*評分方法!$C$6 -> 0 | K18: =AG18*評分方法!$C$7 -> 15 | L18: =AH18*評分方法!$C$8 -> 15 | M18: =AI18*評分方法!$C$9 -> 10 | N18: =AJ18*評分方法!$C$10 -> 9.648 | O18: =AK18*評分方法!$C$11 -> 2.5 | P18: =AL18*評分方法!$C$12 -> 5 | Q18: 11870990 | R18: 117641603 | S18: 10 億以下 | T18: apache-2.0 | U18: 寬鬆授權 | V18: safetensors;pytorch;onnx | W18: 原始開發組織 | X18: 標示支援 | Y18: nreimers/mMiniLMv2-L12-H384-distilled-from-XLMR-Large | Z18: quantized | AA18: text-ranking | AB18: 作者標示 | AC18: 量化版本 | AD18: https://huggingface.co/cross-encoder/mmarco-mMiniLMv2-L12-H384-v1 | AE18: 0.9 | AF18: 0 | AG18: 1 | AH18: 1 | AI18: 1 | AJ18: 0.9648 | AK18: 0.5 | AL18: 1 | AM18: =COUNTIFS($D$2:$D$2501,D18,$G$2:$G$2501,">"&G18)+COUNTIFS($D$2:D18,D18,$G$2:G18,G18) -> 7 | AN18: =D18&"|"&AM18 -> 檢索與情資關聯|7
A19: =RANK(G19,$G$2:$G$2501)+COUNTIF($G$2:G19,G19)-1 -> 18 | B19: intfloat/multilingual-e5-large-instruct | C19: intfloat | D19: 檢索與情資關聯 | E19: 威脅情資語意搜尋、相似告警比對、事件知識庫 RAG | G19: =ROUND(SUM(I19:P19),3) -> 84.132 | H19: =IF(G19>=評分方法!$C$16,"優先評估",IF(G19>=評分方法!$C$17,"列入候選",IF(G19>=評分方法!$C$18,"特定情境","不建議"))) -> 優先評估 | I19: =AE19*評分方法!$C$5 -> 27 | J19: =AF19*評分方法!$C$6 -> 0 | K19: =AG19*評分方法!$C$7 -> 15 | L19: =AH19*評分方法!$C$8 -> 15 | M19: =AI19*評分方法!$C$9 -> 10 | N19: =AJ19*評分方法!$C$10 -> 9.632 | O19: =AK19*評分方法!$C$11 -> 2.5 | P19: =AL19*評分方法!$C$12 -> 5 | Q19: 11123160 | R19: 559890432 | S19: 10 億以下 | T19: mit | U19: 寬鬆授權 | V19: safetensors;onnx | W19: 原始開發組織 | X19: 標示支援 | AA19: feature-extraction | AB19: 作者標示 | AD19: https://huggingface.co/intfloat/multilingual-e5-large-instruct | AE19: 0.9 | AF19: 0 | AG19: 1 | AH19: 1 | AI19: 1 | AJ19: 0.9632 | AK19: 0.5 | AL19: 1 | AM19: =COUNTIFS($D$2:$D$2501,D19,$G$2:$G$2501,">"&G19)+COUNTIFS($D$2:D19,D19,$G$2:G19,G19) -> 8 | AN19: =D19&"|"&AM19 -> 檢索與情資關聯|8
A20: =RANK(G20,$G$2:$G$2501)+COUNTIF($G$2:G20,G20)-1 -> 19 | B20: microsoft/harrier-oss-v1-270m | C20: microsoft | D20: 檢索與情資關聯 | E20: 威脅情資語意搜尋、相似告警比對、事件知識庫 RAG | G20: =ROUND(SUM(I20:P20),3) -> 84.12 | H20: =IF(G20>=評分方法!$C$16,"優先評估",IF(G20>=評分方法!$C$17,"列入候選",IF(G20>=評分方法!$C$18,"特定情境","不建議"))) -> 優先評估 | I20: =AE20*評分方法!$C$5 -> 27 | J20: =AF20*評分方法!$C$6 -> 0 | K20: =AG20*評分方法!$C$7 -> 15 | L20: =AH20*評分方法!$C$8 -> 15 | M20: =AI20*評分方法!$C$9 -> 10 | N20: =AJ20*評分方法!$C$10 -> 8.12 | O20: =AK20*評分方法!$C$11 -> 4 | P20: =AL20*評分方法!$C$12 -> 5 | Q20: 1729392 | R20: 268098176 | S20: 10 億以下 | T20: mit | U20: 寬鬆授權 | V20: safetensors | W20: 原始開發組織 | X20: 標示支援 | AA20: feature-extraction | AB20: 作者標示 | AD20: https://huggingface.co/microsoft/harrier-oss-v1-270m | AE20: 0.9 | AF20: 0 | AG20: 1 | AH20: 1 | AI20: 1 | AJ20: 0.812 | AK20: 0.8 | AL20: 1 | AM20: =COUNTIFS($D$2:$D$2501,D20,$G$2:$G$2501,">"&G20)+COUNTIFS($D$2:D20,D20,$G$2:G20,G20) -> 9 | AN20: =D20&"|"&AM20 -> 檢索與情資關聯|9
A21: =RANK(G21,$G$2:$G$2501)+COUNTIF($G$2:G21,G21)-1 -> 20 | B21: ibm-granite/granite-embedding-311m-multilingual-r2 | C21: ibm-granite | D21: 檢索與情資關聯 | E21: 威脅情資語意搜尋、相似告警比對、事件知識庫 RAG | G21: =ROUND(SUM(I21:P21),3) -> 84.028 | H21: =IF(G21>=評分方法!$C$16,"優先評估",IF(G21>=評分方法!$C$17,"列入候選",IF(G21>=評分方法!$C$18,"特定情境","不建議"))) -> 優先評估 | I21: =AE21*評分方法!$C$5 -> 27 | J21: =AF21*評分方法!$C$6 -> 0 | K21: =AG21*評分方法!$C$7 -> 15 | L21: =AH21*評分方法!$C$8 -> 15 | M21: =AI21*評分方法!$C$9 -> 10 | N21: =AJ21*評分方法!$C$10 -> 7.028 | O21: =AK21*評分方法!$C$11 -> 5 | P21: =AL21*評分方法!$C$12 -> 5 | Q21: 930953 | R21: 311664384 | S21: 10 億以下 | T21: apache-2.0 | U21: 寬鬆授權 | V21: safetensors;pytorch;onnx | W21: 原始開發組織 | X21: 標示支援 | AA21: feature-extraction | AB21: 作者標示 | AD21: https://huggingface.co/ibm-granite/granite-embedding-311m-multilingual-r2 | AE21: 0.9 | AF21: 0 | AG21: 1 | AH21: 1 | AI21: 1 | AJ21: 0.7028 | AK21: 1 | AL21: 1 | AM21: =COUNTIFS($D$2:$D$2501,D21,$G$2:$G$2501,">"&G21)+COUNTIFS($D$2:D21,D21,$G$2:G21,G21) -> 10 | AN21: =D21&"|"&AM21 -> 檢索與情資關聯|10
A22: =RANK(G22,$G$2:$G$2501)+COUNTIF($G$2:G22,G22)-1 -> 21 | B22: Snowflake/snowflake-arctic-embed-l-v2.0 | C22: Snowflake | D22: 檢索與情資關聯 | E22: 威脅情資語意搜尋、相似告警比對、事件知識庫 RAG | G22: =ROUND(SUM(I22:P22),3) -> 83.952 | H22: =IF(G22>=評分方法!$C$16,"優先評估",IF(G22>=評分方法!$C$17,"列入候選",IF(G22>=評分方法!$C$18,"特定情境","不建議"))) -> 優先評估 | I22: =AE22*評分方法!$C$5 -> 27 | J22: =AF22*評分方法!$C$6 -> 0 | K22: =AG22*評分方法!$C$7 -> 15 | L22: =AH22*評分方法!$C$8 -> 15 | M22: =AI22*評分方法!$C$9 -> 10 | N22: =AJ22*評分方法!$C$10 -> 9.452 | O22: =AK22*評分方法!$C$11 -> 2.5 | P22: =AL22*評分方法!$C$12 -> 5 | Q22: 8047966 | R22: 567754752 | S22: 10 億以下 | T22: apache-2.0 | U22: 寬鬆授權 | V22: safetensors;onnx | W22: 原始開發組織 | X22: 標示支援 | AA22: sentence-similarity | AB22: 作者標示 | AD22: https://huggingface.co/Snowflake/snowflake-arctic-embed-l-v2.0 | AE22: 0.9 | AF22: 0 | AG22: 1 | AH22: 1 | AI22: 1 | AJ22: 0.9452 | AK22: 0.5 | AL22: 1 | AM22: =COUNTIFS($D$2:$D$2501,D22,$G$2:$G$2501,">"&G22)+COUNTIFS($D$2:D22,D22,$G$2:G22,G22) -> 11 | AN22: =D22&"|"&AM22 -> 檢索與情資關聯|11
A23: =RANK(G23,$G$2:$G$2501)+COUNTIF($G$2:G23,G23)-1 -> 22 | B23: sentence-transformers/distiluse-base-multilingual-cased-v1 | C23: sentence-transformers | D23: 檢索與情資關聯 | E23: 威脅情資語意搜尋、相似告警比對、事件知識庫 RAG | G23: =ROUND(SUM(I23:P23),3) -> 83.908 | H23: =IF(G23>=評分方法!$C$16,"優先評估",IF(G23>=評分方法!$C$17,"列入候選",IF(G23>=評分方法!$C$18,"特定情境","不建議"))) -> 優先評估 | I23: =AE23*評分方法!$C$5 -> 27 | J23: =AF23*評分方法!$C$6 -> 0 | K23: =AG23*評分方法!$C$7 -> 15 | L23: =AH23*評分方法!$C$8 -> 15 | M23: =AI23*評分方法!$C$9 -> 10 | N23: =AJ23*評分方法!$C$10 -> 9.408 | O23: =AK23*評分方法!$C$11 -> 2.5 | P23: =AL23*評分方法!$C$12 -> 5 | Q23: 7375555 | R23: 134734080 | S23: 10 億以下 | T23: apache-2.0 | U23: 寬鬆授權 | V23: safetensors;pytorch;onnx;tensorflow | W23: 原始開發組織 | X23: 標示支援 | AA23: sentence-similarity | AB23: 作者標示 | AD23: https://huggingface.co/sentence-transformers/distiluse-base-multilingual-cased-v1 | AE23: 0.9 | AF23: 0 | AG23: 1 | AH23: 1 | AI23: 1 | AJ23: 0.9408 | AK23: 0.5 | AL23: 1 | AM23: =COUNTIFS($D$2:$D$2501,D23,$G$2:$G$2501,">"&G23)+COUNTIFS($D$2:D23,D23,$G$2:G23,G23) -> 12 | AN23: =D23&"|"&AM23 -> 檢索與情資關聯|12
A24: =RANK(G24,$G$2:$G$2501)+COUNTIF($G$2:G24,G24)-1 -> 23 | B24: sentence-transformers/distiluse-base-multilingual-cased-v2 | C24: sentence-transformers | D24: 檢索與情資關聯 | E24: 威脅情資語意搜尋、相似告警比對、事件知識庫 RAG | G24: =ROUND(SUM(I24:P24),3) -> 83.84 | H24: =IF(G24>=評分方法!$C$16,"優先評估",IF(G24>=評分方法!$C$17,"列入候選",IF(G24>=評分方法!$C$18,"特定情境","不建議"))) -> 優先評估 | I24: =AE24*評分方法!$C$5 -> 27 | J24: =AF24*評分方法!$C$6 -> 0 | K24: =AG24*評分方法!$C$7 -> 15 | L24: =AH24*評分方法!$C$8 -> 15 | M24: =AI24*評分方法!$C$9 -> 10 | N24: =AJ24*評分方法!$C$10 -> 9.34 | O24: =AK24*評分方法!$C$11 -> 2.5 | P24: =AL24*評分方法!$C$12 -> 5 | Q24: 6560606 | R24: 134734080 | S24: 10 億以下 | T24: apache-2.0 | U24: 寬鬆授權 | V24: safetensors;pytorch;onnx;tensorflow | W24: 原始開發組織 | X24: 標示支援 | AA24: sentence-similarity | AB24: 作者標示 | AD24: https://huggingface.co/sentence-transformers/distiluse-base-multilingual-cased-v2 | AE24: 0.9 | AF24: 0 | AG24: 1 | AH24: 1 | AI24: 1 | AJ24: 0.934 | AK24: 0.5 | AL24: 1 | AM24: =COUNTIFS($D$2:$D$2501,D24,$G$2:$G$2501,">"&G24)+COUNTIFS($D$2:D24,D24,$G$2:G24,G24) -> 13 | AN24: =D24&"|"&AM24 -> 檢索與情資關聯|13
A25: =RANK(G25,$G$2:$G$2501)+COUNTIF($G$2:G25,G25)-1 -> 24 | B25: sentence-transformers/LaBSE | C25: sentence-transformers | D25: 檢索與情資關聯 | E25: 威脅情資語意搜尋、相似告警比對、事件知識庫 RAG | G25: =ROUND(SUM(I25:P25),3) -> 83.7 | H25: =IF(G25>=評分方法!$C$16,"優先評估",IF(G25>=評分方法!$C$17,"列入候選",IF(G25>=評分方法!$C$18,"特定情境","不建議"))) -> 優先評估 | I25: =AE25*評分方法!$C$5 -> 27 | J25: =AF25*評分方法!$C$6 -> 0 | K25: =AG25*評分方法!$C$7 -> 15 | L25: =AH25*評分方法!$C$8 -> 15 | M25: =AI25*評分方法!$C$9 -> 10 | N25: =AJ25*評分方法!$C$10 -> 9.2 | O25: =AK25*評分方法!$C$11 -> 2.5 | P25: =AL25*評分方法!$C$12 -> 5 | Q25: 5106553 | R25: 470927360 | S25: 10 億以下 | T25: apache-2.0 | U25: 寬鬆授權 | V25: safetensors;pytorch;onnx;tensorflow;flax | W25: 原始開發組織 | X25: 標示支援 | AA25: sentence-similarity | AB25: 作者標示 | AD25: https://huggingface.co/sentence-transformers/LaBSE | AE25: 0.9 | AF25: 0 | AG25: 1 | AH25: 1 | AI25: 1 | AJ25: 0.92 | AK25: 0.5 | AL25: 1 | AM25: =COUNTIFS($D$2:$D$2501,D25,$G$2:$G$2501,">"&G25)+COUNTIFS($D$2:D25,D25,$G$2:G25,G25) -> 14 | AN25: =D25&"|"&AM25 -> 檢索與情資關聯|14
A26: =RANK(G26,$G$2:$G$2501)+COUNTIF($G$2:G26,G26)-1 -> 25 | B26: allenai/wildguard | C26: allenai | D26: AI 應用防護 | E26: AI 應用的提示注入、越獄與有害內容偵測 | F26: AI 應用防護 | G26: =ROUND(SUM(I26:P26),3) -> 83.138 | H26: =IF(G26>=評分方法!$C$16,"優先評估",IF(G26>=評分方法!$C$17,"列入候選",IF(G26>=評分方法!$C$18,"特定情境","不建議"))) -> 優先評估 | I26: =AE26*評分方法!$C$5 -> 25.5 | J26: =AF26*評分方法!$C$6 -> 10 | K26: =AG26*評分方法!$C$7 -> 15 | L26: =AH26*評分方法!$C$8 -> 13.05 | M26: =AI26*評分方法!$C$9 -> 10 | N26: =AJ26*評分方法!$C$10 -> 7.088 | O26: =AK26*評分方法!$C$11 -> 2.5 | P26: =AL26*評分方法!$C$12 -> 0 | Q26: 954952 | R26: 7248031744 | S26: 10 億至 100 億 | T26: apache-2.0 | U26: 寬鬆授權 | V26: safetensors;pytorch | W26: 原始開發組織 | X26: 未標示中文 | AA26: text-generation | AB26: 作者標示 | AD26: https://huggingface.co/allenai/wildguard | AE26: 0.85 | AF26: 1 | AG26: 1 | AH26: 0.87 | AI26: 1 | AJ26: 0.7088 | AK26: 0.5 | AL26: 0 | AM26: =COUNTIFS($D$2:$D$2501,D26,$G$2:$G$2501,">"&G26)+COUNTIFS($D$2:D26,D26,$G$2:G26,G26) -> 5 | AN26: =D26&"|"&AM26 -> AI 應用防護|5
A27: =RANK(G27,$G$2:$G$2501)+COUNTIF($G$2:G27,G27)-1 -> 26 | B27: nvidia/Nemotron-3.5-Content-Safety | C27: nvidia | D27: AI 應用防護 | E27: AI 應用的提示注入、越獄與有害內容偵測 | F27: AI 應用防護 | G27: =ROUND(SUM(I27:P27),3) -> 83.09 | H27: =IF(G27>=評分方法!$C$16,"優先評估",IF(G27>=評分方法!$C$17,"列入候選",IF(G27>=評分方法!$C$18,"特定情境","不建議"))) -> 優先評估 | I27: =AE27*評分方法!$C$5 -> 25.5 | J27: =AF27*評分方法!$C$6 -> 10 | K27: =AG27*評分方法!$C$7 -> 15 | L27: =AH27*評分方法!$C$8 -> 13.05 | M27: =AI27*評分方法!$C$9 -> 6 | N27: =AJ27*評分方法!$C$10 -> 3.54 | O27: =AK27*評分方法!$C$11 -> 5 | P27: =AL27*評分方法!$C$12 -> 5 | Q27: 354945 | R27: 4300079472 | S27: 10 億至 100 億 | T27: other | U27: 自訂授權, 需法務審查 | V27: safetensors | W27: 原始開發組織 | X27: 標示支援 | AA27: text-generation | AB27: 依模型架構推定 | AC27: 任務類型依模型架構推定; 授權需確認 | AD27: https://huggingface.co/nvidia/Nemotron-3.5-Content-Safety | AE27: 0.85 | AF27: 1 | AG27: 1 | AH27: 0.87 | AI27: 0.6 | AJ27: 0.354 | AK27: 1 | AL27: 1 | AM27: =COUNTIFS($D$2:$D$2501,D27,$G$2:$G$2501,">"&G27)+COUNTIFS($D$2:D27,D27,$G$2:G27,G27) -> 6 | AN27: =D27&"|"&AM27 -> AI 應用防護|6
A28: =RANK(G28,$G$2:$G$2501)+COUNTIF($G$2:G28,G28)-1 -> 27 | B28: LocalAI-io/privacy-filter-multilingual-GGUF | C28: LocalAI-io | D28: 個資偵測與去識別化 | E28: 個資偵測與遮蔽 | F28: 個資偵測與去識別化 | G28: =ROUND(SUM(I28:P28),3) -> 82.676 | H28: =IF(G28>=評分方法!$C$16,"優先評估",IF(G28>=評分方法!$C$17,"列入候選",IF(G28>=評分方法!$C$18,"特定情境","不建議"))) -> 優先評估 | I28: =AE28*評分方法!$C$5 -> 28.5 | J28: =AF28*評分方法!$C$6 -> 10 | K28: =AG28*評分方法!$C$7 -> 4.95 | L28: =AH28*評分方法!$C$8 -> 13.05 | M28: =AI28*評分方法!$C$9 -> 10 | N28: =AJ28*評分方法!$C$10 -> 6.176 | O28: =AK28*評分方法!$C$11 -> 5 | P28: =AL28*評分方法!$C$12 -> 5 | Q28: 661379 | R28: 1399604809 | S28: 10 億至 100 億 | T28: apache-2.0 | U28: 寬鬆授權 | V28: gguf | W28: 其他帳號 | X28: 標示支援 | Y28: OpenMed/privacy-filter-multilingual | Z28: quantized | AA28: token-classification | AB28: 作者標示 | AC28: 量化版本 | AD28: https://huggingface.co/LocalAI-io/privacy-filter-multilingual-GGUF | AE28: 0.95 | AF28: 1 | AG28: 0.33 | AH28: 0.87 | AI28: 1 | AJ28: 0.6176 | AK28: 1 | AL28: 1 | AM28: =COUNTIFS($D$2:$D$2501,D28,$G$2:$G$2501,">"&G28)+COUNTIFS($D$2:D28,D28,$G$2:G28,G28) -> 4 | AN28: =D28&"|"&AM28 -> 個資偵測與去識別化|4
A29: =RANK(G29,$G$2:$G$2501)+COUNTIF($G$2:G29,G29)-1 -> 28 | B29: mistralai/Ministral-3-3B-Instruct-2512 | C29: mistralai | D29: 分析與報告生成 | E29: 告警分診摘要、ATT&CK 對映、事件報告初稿 (需人工確認) | G29: =ROUND(SUM(I29:P29),3) -> 82.322 | H29: =IF(G29>=評分方法!$C$16,"優先評估",IF(G29>=評分方法!$C$17,"列入候選",IF(G29>=評分方法!$C$18,"特定情境","不建議"))) -> 優先評估 | I29: =AE29*評分方法!$C$5 -> 25.5 | J29: =AF29*評分方法!$C$6 -> 0 | K29: =AG29*評分方法!$C$7 -> 15 | L29: =AH29*評分方法!$C$8 -> 13.05 | M29: =AI29*評分方法!$C$9 -> 10 | N29: =AJ29*評分方法!$C$10 -> 8.772 | O29: =AK29*評分方法!$C$11 -> 5 | P29: =AL29*評分方法!$C$12 -> 5 | Q29: 2978637 | R29: 3849090048 | S29: 10 億至 100 億 | T29: apache-2.0 | U29: 寬鬆授權 | V29: safetensors | W29: 原始開發組織 | X29: 標示支援 | Y29: mistralai/Ministral-3-3B-Base-2512 | Z29: quantized | AA29: text-generation | AB29: 依模型架構推定 | AC29: 任務類型依模型架構推定; 量化版本 | AD29: https://huggingface.co/mistralai/Ministral-3-3B-Instruct-2512 | AE29: 0.85 | AF29: 0 | AG29: 1 | AH29: 0.87 | AI29: 1 | AJ29: 0.8772 | AK29: 1 | AL29: 1 | AM29: =COUNTIFS($D$2:$D$2501,D29,$G$2:$G$2501,">"&G29)+COUNTIFS($D$2:D29,D29,$G$2:G29,G29) -> 1 | AN29: =D29&"|"&AM29 -> 分析與報告生成|1
A30: =RANK(G30,$G$2:$G$2501)+COUNTIF($G$2:G30,G30)-1 -> 29 | B30: fastino/gliner2.5-multi-v1 | C30: fastino | D30: 實體擷取與去識別化 | E30: 從報告擷取 IOC 與實體, log 與工單個資遮蔽 | G30: =ROUND(SUM(I30:P30),3) -> 82.32 | H30: =IF(G30>=評分方法!$C$16,"優先評估",IF(G30>=評分方法!$C$17,"列入候選",IF(G30>=評分方法!$C$18,"特定情境","不建議"))) -> 優先評估 | I30: =AE30*評分方法!$C$5 -> 28.5 | J30: =AF30*評分方法!$C$6 -> 0 | K30: =AG30*評分方法!$C$7 -> 15 | L30: =AH30*評分方法!$C$8 -> 15 | M30: =AI30*評分方法!$C$9 -> 10 | N30: =AJ30*評分方法!$C$10 -> 3.82 | O30: =AK30*評分方法!$C$11 -> 5 | P30: =AL30*評分方法!$C$12 -> 5 | Q30: 392554 | R30: 287355159 | S30: 10 億以下 | T30: apache-2.0 | U30: 寬鬆授權 | V30: safetensors | W30: 原始開發組織 | X30: 標示支援 | AA30: token-classification | AB30: 依名稱推定 | AC30: 任務類型依名稱推定 | AD30: https://huggingface.co/fastino/gliner2.5-multi-v1 | AE30: 0.95 | AF30: 0 | AG30: 1 | AH30: 1 | AI30: 1 | AJ30: 0.382 | AK30: 1 | AL30: 1 | AM30: =COUNTIFS($D$2:$D$2501,D30,$G$2:$G$2501,">"&G30)+COUNTIFS($D$2:D30,D30,$G$2:G30,G30) -> 1 | AN30: =D30&"|"&AM30 -> 實體擷取與去識別化|1
A31: =RANK(G31,$G$2:$G$2501)+COUNTIF($G$2:G31,G31)-1 -> 30 | B31: fastino/gliner2-base-v1 | C31: fastino | D31: 實體擷取與去識別化 | E31: 從報告擷取 IOC 與實體, log 與工單個資遮蔽 | G31: =ROUND(SUM(I31:P31),3) -> 82.284 | H31: =IF(G31>=評分方法!$C$16,"優先評估",IF(G31>=評分方法!$C$17,"列入候選",IF(G31>=評分方法!$C$18,"特定情境","不建議"))) -> 優先評估 | I31: =AE31*評分方法!$C$5 -> 28.5 | J31: =AF31*評分方法!$C$6 -> 0 | K31: =AG31*評分方法!$C$7 -> 15 | L31: =AH31*評分方法!$C$8 -> 15 | M31: =AI31*評分方法!$C$9 -> 10 | N31: =AJ31*評分方法!$C$10 -> 8.784 | O31: =AK31*評分方法!$C$11 -> 5 | P31: =AL31*評分方法!$C$12 -> 0 | Q31: 3031150 | R31: 208476821 | S31: 10 億以下 | T31: apache-2.0 | U31: 寬鬆授權 | V31: safetensors | W31: 原始開發組織 | X31: 未標示中文 | AA31: token-classification | AB31: 依名稱推定 | AC31: 任務類型依名稱推定 | AD31: https://huggingface.co/fastino/gliner2-base-v1 | AE31: 0.95 | AF31: 0 | AG31: 1 | AH31: 1 | AI31: 1 | AJ31: 0.8784 | AK31: 1 | AL31: 0 | AM31: =COUNTIFS($D$2:$D$2501,D31,$G$2:$G$2501,">"&G31)+COUNTIFS($D$2:D31,D31,$G$2:G31,G31) -> 2 | AN31: =D31&"|"&AM31 -> 實體擷取與去識別化|2
A32: =RANK(G32,$G$2:$G$2501)+COUNTIF($G$2:G32,G32)-1 -> 31 | B32: garak-llm/garak-refusal-detector | C32: garak-llm | D32: AI 紅隊評估 | E32: LLM 弱點掃描工具 garak 的偵測元件 | F32: AI 紅隊評估 | G32: =ROUND(SUM(I32:P32),3) -> 82.04 | H32: =IF(G32>=評分方法!$C$16,"優先評估",IF(G32>=評分方法!$C$17,"列入候選",IF(G32>=評分方法!$C$18,"特定情境","不建議"))) -> 優先評估 | I32: =AE32*評分方法!$C$5 -> 30 | J32: =AF32*評分方法!$C$6 -> 10 | K32: =AG32*評分方法!$C$7 -> 15 | L32: =AH32*評分方法!$C$8 -> 15 | M32: =AI32*評分方法!$C$9 -> 6 | N32: =AJ32*評分方法!$C$10 -> 2.04 | O32: =AK32*評分方法!$C$11 -> 4 | P32: =AL32*評分方法!$C$12 -> 0 | Q32: 213425 | R32: 149606402 | S32: 10 億以下 | T32: other | U32: 自訂授權, 需法務審查 | V32: safetensors | W32: 原始開發組織 | X32: 未標示中文 | Y32: answerdotai/ModernBERT-base | Z32: finetune | AA32: text-classification | AB32: 作者標示 | AC32: 授權需確認 | AD32: https://huggingface.co/garak-llm/garak-refusal-detector | AE32: 1 | AF32: 1 | AG32: 1 | AH32: 1 | AI32: 0.6 | AJ32: 0.204 | AK32: 0.8 | AL32: 0 | AM32: =COUNTIFS($D$2:$D$2501,D32,$G$2:$G$2501,">"&G32)+COUNTIFS($D$2:D32,D32,$G$2:G32,G32) -> 1 | AN32: =D32&"|"&AM32 -> AI 紅隊評估|1
A33: =RANK(G33,$G$2:$G$2501)+COUNTIF($G$2:G33,G33)-1 -> 32 | B33: sentence-transformers/all-MiniLM-L6-v2 | C33: sentence-transformers | D33: 檢索與情資關聯 | E33: 威脅情資語意搜尋、相似告警比對、事件知識庫 RAG | G33: =ROUND(SUM(I33:P33),3) -> 82 | H33: =IF(G33>=評分方法!$C$16,"優先評估",IF(G33>=評分方法!$C$17,"列入候選",IF(G33>=評分方法!$C$18,"特定情境","不建議"))) -> 優先評估 | I33: =AE33*評分方法!$C$5 -> 27 | J33: =AF33*評分方法!$C$6 -> 0 | K33: =AG33*評分方法!$C$7 -> 15 | L33: =AH33*評分方法!$C$8 -> 15 | M33: =AI33*評分方法!$C$9 -> 10 | N33: =AJ33*評分方法!$C$10 -> 10 | O33: =AK33*評分方法!$C$11 -> 5 | P33: =AL33*評分方法!$C$12 -> 0 | Q33: 1541997836 | R33: 22713728 | S33: 10 億以下 | T33: apache-2.0 | U33: 寬鬆授權 | V33: safetensors;pytorch;onnx;tensorflow | W33: 原始開發組織 | X33: 未標示中文 | Y33: nreimers/MiniLM-L6-H384-uncased | Z33: quantized | AA33: sentence-similarity | AB33: 作者標示 | AC33: 量化版本 | AD33: https://huggingface.co/sentence-transformers/all-MiniLM-L6-v2 | AE33: 0.9 | AF33: 0 | AG33: 1 | AH33: 1 | AI33: 1 | AJ33: 1 | AK33: 1 | AL33: 0 | AM33: =COUNTIFS($D$2:$D$2501,D33,$G$2:$G$2501,">"&G33)+COUNTIFS($D$2:D33,D33,$G$2:G33,G33) -> 15 | AN33: =D33&"|"&AM33 -> 檢索與情資關聯|15
A34: =RANK(G34,$G$2:$G$2501)+COUNTIF($G$2:G34,G34)-1 -> 33 | B34: cross-encoder/ms-marco-MiniLM-L6-v2 | C34: cross-encoder | D34: 檢索與情資關聯 | E34: 威脅情資語意搜尋、相似告警比對、事件知識庫 RAG | G34: =ROUND(SUM(I34:P34),3) -> 81.996 | H34: =IF(G34>=評分方法!$C$16,"優先評估",IF(G34>=評分方法!$C$17,"列入候選",IF(G34>=評分方法!$C$18,"特定情境","不建議"))) -> 優先評估 | I34: =AE34*評分方法!$C$5 -> 27 | J34: =AF34*評分方法!$C$6 -> 0 | K34: =AG34*評分方法!$C$7 -> 15 | L34: =AH34*評分方法!$C$8 -> 15 | M34: =AI34*評分方法!$C$9 -> 10 | N34: =AJ34*評分方法!$C$10 -> 9.996 | O34: =AK34*評分方法!$C$11 -> 5 | P34: =AL34*評分方法!$C$12 -> 0 | Q34: 503002254 | R34: 22714113 | S34: 10 億以下 | T34: apache-2.0 | U34: 寬鬆授權 | V34: safetensors;pytorch;onnx;flax | W34: 原始開發組織 | X34: 未標示中文 | Y34: cross-encoder/ms-marco-MiniLM-L12-v2 | Z34: quantized | AA34: text-ranking | AB34: 作者標示 | AC34: 量化版本 | AD34: https://huggingface.co/cross-encoder/ms-marco-MiniLM-L6-v2 | AE34: 0.9 | AF34: 0 | AG34: 1 | AH34: 1 | AI34: 1 | AJ34: 0.9996 | AK34: 1 | AL34: 0 | AM34: =COUNTIFS($D$2:$D$2501,D34,$G$2:$G$2501,">"&G34)+COUNTIFS($D$2:D34,D34,$G$2:G34,G34) -> 16 | AN34: =D34&"|"&AM34 -> 檢索與情資關聯|16
A35: =RANK(G35,$G$2:$G$2501)+COUNTIF($G$2:G35,G35)-1 -> 34 | B35: fastino/gliner2-large-v1 | C35: fastino | D35: 實體擷取與去識別化 | E35: 從報告擷取 IOC 與實體, log 與工單個資遮蔽 | G35: =ROUND(SUM(I35:P35),3) -> 81.788 | H35: =IF(G35>=評分方法!$C$16,"優先評估",IF(G35>=評分方法!$C$17,"列入候選",IF(G35>=評分方法!$C$18,"特定情境","不建議"))) -> 優先評估 | I35: =AE35*評分方法!$C$5 -> 28.5 | J35: =AF35*評分方法!$C$6 -> 0 | K35: =AG35*評分方法!$C$7 -> 15 | L35: =AH35*評分方法!$C$8 -> 15 | M35: =AI35*評分方法!$C$9 -> 10 | N35: =AJ35*評分方法!$C$10 -> 8.288 | O35: =AK35*評分方法!$C$11 -> 5 | P35: =AL35*評分方法!$C$12 -> 0 | Q35: 1925638 | R35: 486444053 | S35: 10 億以下 | T35: apache-2.0 | U35: 寬鬆授權 | V35: safetensors | W35: 原始開發組織 | X35: 未標示中文 | AA35: token-classification | AB35: 依名稱推定 | AC35: 任務類型依名稱推定 | AD35: https://huggingface.co/fastino/gliner2-large-v1 | AE35: 0.95 | AF35: 0 | AG35: 1 | AH35: 1 | AI35: 1 | AJ35: 0.8288 | AK35: 1 | AL35: 0 | AM35: =COUNTIFS($D$2:$D$2501,D35,$G$2:$G$2501,">"&G35)+COUNTIFS($D$2:D35,D35,$G$2:G35,G35) -> 3 | AN35: =D35&"|"&AM35 -> 實體擷取與去識別化|3
A36: =RANK(G36,$G$2:$G$2501)+COUNTIF($G$2:G36,G36)-1 -> 35 | B36: AungMoonLord/bert-log-anomaly-detection | C36: AungMoonLord | D36: 日誌異常偵測 | E36: 日誌序列異常分類 | F36: 日誌異常偵測 | G36: =ROUND(SUM(I36:P36),3) -> 81.654 | H36: =IF(G36>=評分方法!$C$16,"優先評估",IF(G36>=評分方法!$C$17,"列入候選",IF(G36>=評分方法!$C$18,"特定情境","不建議"))) -> 優先評估 | I36: =AE36*評分方法!$C$5 -> 30 | J36: =AF36*評分方法!$C$6 -> 10 | K36: =AG36*評分方法!$C$7 -> 4.95 | L36: =AH36*評分方法!$C$8 -> 15 | M36: =AI36*評分方法!$C$9 -> 10 | N36: =AJ36*評分方法!$C$10 -> 6.204 | O36: =AK36*評分方法!$C$11 -> 4 | P36: =AL36*評分方法!$C$12 -> 1.5 | Q36: 669544 | R36: 109483778 | S36: 10 億以下 | T36: apache-2.0 | U36: 寬鬆授權 | V36: safetensors | W36: 其他帳號 | X36: 未標示 | Y36: google-bert/bert-base-uncased | Z36: finetune | AA36: text-classification | AB36: 作者標示 | AD36: https://huggingface.co/AungMoonLord/bert-log-anomaly-detection | AE36: 1 | AF36: 1 | AG36: 0.33 | AH36: 1 | AI36: 1 | AJ36: 0.6204 | AK36: 0.8 | AL36: 0.3 | AM36: =COUNTIFS($D$2:$D$2501,D36,$G$2:$G$2501,">"&G36)+COUNTIFS($D$2:D36,D36,$G$2:G36,G36) -> 1 | AN36: =D36&"|"&AM36 -> 日誌異常偵測|1
A37: =RANK(G37,$G$2:$G$2501)+COUNTIF($G$2:G37,G37)-1 -> 36 | B37: sentence-transformers/clip-ViT-B-32-multilingual-v1 | C37: sentence-transformers | D37: 檢索與情資關聯 | E37: 威脅情資語意搜尋、相似告警比對、事件知識庫 RAG | G37: =ROUND(SUM(I37:P37),3) -> 81.58 | H37: =IF(G37>=評分方法!$C$16,"優先評估",IF(G37>=評分方法!$C$17,"列入候選",IF(G37>=評分方法!$C$18,"特定情境","不建議"))) -> 優先評估 | I37: =AE37*評分方法!$C$5 -> 27 | J37: =AF37*評分方法!$C$6 -> 0 | K37: =AG37*評分方法!$C$7 -> 15 | L37: =AH37*評分方法!$C$8 -> 15 | M37: =AI37*評分方法!$C$9 -> 10 | N37: =AJ37*評分方法!$C$10 -> 7.08 | O37: =AK37*評分方法!$C$11 -> 2.5 | P37: =AL37*評分方法!$C$12 -> 5 | Q37: 951107 | R37: 134734080 | S37: 10 億以下 | T37: apache-2.0 | U37: 寬鬆授權 | V37: safetensors;pytorch;onnx;tensorflow | W37: 原始開發組織 | X37: 標示支援 | AA37: sentence-similarity | AB37: 作者標示 | AD37: https://huggingface.co/sentence-transformers/clip-ViT-B-32-multilingual-v1 | AE37: 0.9 | AF37: 0 | AG37: 1 | AH37: 1 | AI37: 1 | AJ37: 0.708 | AK37: 0.5 | AL37: 1 | AM37: =COUNTIFS($D$2:$D$2501,D37,$G$2:$G$2501,">"&G37)+COUNTIFS($D$2:D37,D37,$G$2:G37,G37) -> 17 | AN37: =D37&"|"&AM37 -> 檢索與情資關聯|17
A38: =RANK(G38,$G$2:$G$2501)+COUNTIF($G$2:G38,G38)-1 -> 37 | B38: google/canine-c | C38: google | D38: 檢索與情資關聯 | E38: 威脅情資語意搜尋、相似告警比對、事件知識庫 RAG | G38: =ROUND(SUM(I38:P38),3) -> 81.28 | H38: =IF(G38>=評分方法!$C$16,"優先評估",IF(G38>=評分方法!$C$17,"列入候選",IF(G38>=評分方法!$C$18,"特定情境","不建議"))) -> 優先評估 | I38: =AE38*評分方法!$C$5 -> 27 | J38: =AF38*評分方法!$C$6 -> 0 | K38: =AG38*評分方法!$C$7 -> 15 | L38: =AH38*評分方法!$C$8 -> 15 | M38: =AI38*評分方法!$C$9 -> 10 | N38: =AJ38*評分方法!$C$10 -> 8.28 | O38: =AK38*評分方法!$C$11 -> 1 | P38: =AL38*評分方法!$C$12 -> 5 | Q38: 1923921 | R38: 132099328 | S38: 10 億以下 | T38: apache-2.0 | U38: 寬鬆授權 | V38: safetensors;pytorch | W38: 原始開發組織 | X38: 標示支援 | AA38: feature-extraction | AB38: 作者標示 | AD38: https://huggingface.co/google/canine-c | AE38: 0.9 | AF38: 0 | AG38: 1 | AH38: 1 | AI38: 1 | AJ38: 0.828 | AK38: 0.2 | AL38: 1 | AM38: =COUNTIFS($D$2:$D$2501,D38,$G$2:$G$2501,">"&G38)+COUNTIFS($D$2:D38,D38,$G$2:G38,G38) -> 18 | AN38: =D38&"|"&AM38 -> 檢索與情資關聯|18
A39: =RANK(G39,$G$2:$G$2501)+COUNTIF($G$2:G39,G39)-1 -> 38 | B39: google/gemma-4-31B-it-assistant | C39: google | D39: 分析與報告生成 | E39: 告警分診摘要、ATT&CK 對映、事件報告初稿 (需人工確認) | G39: =ROUND(SUM(I39:P39),3) -> 80.924 | H39: =IF(G39>=評分方法!$C$16,"優先評估",IF(G39>=評分方法!$C$17,"列入候選",IF(G39>=評分方法!$C$18,"特定情境","不建議"))) -> 優先評估 | I39: =AE39*評分方法!$C$5 -> 24 | J39: =AF39*評分方法!$C$6 -> 0 | K39: =AG39*評分方法!$C$7 -> 15 | L39: =AH39*評分方法!$C$8 -> 15 | M39: =AI39*評分方法!$C$9 -> 10 | N39: =AJ39*評分方法!$C$10 -> 8.924 | O39: =AK39*評分方法!$C$11 -> 5 | P39: =AL39*評分方法!$C$12 -> 3 | Q39: 3586594 | R39: 469518596 | S39: 10 億以下 | T39: apache-2.0 | U39: 寬鬆授權 | V39: safetensors | W39: 原始開發組織 | X39: 大型語言模型, 未標示語言 | AA39: any-to-any | AB39: 作者標示 | AD39: https://huggingface.co/google/gemma-4-31B-it-assistant | AE39: 0.8 | AF39: 0 | AG39: 1 | AH39: 1 | AI39: 1 | AJ39: 0.8924 | AK39: 1 | AL39: 0.6 | AM39: =COUNTIFS($D$2:$D$2501,D39,$G$2:$G$2501,">"&G39)+COUNTIFS($D$2:D39,D39,$G$2:G39,G39) -> 2 | AN39: =D39&"|"&AM39 -> 分析與報告生成|2
A40: =RANK(G40,$G$2:$G$2501)+COUNTIF($G$2:G40,G40)-1 -> 39 | B40: GuardrailsAI/prompt-saturation-attack-detector | C40: GuardrailsAI | D40: AI 應用防護 | E40: AI 應用的提示注入、越獄與有害內容偵測 | F40: AI 應用防護 | G40: =ROUND(SUM(I40:P40),3) -> 80.852 | H40: =IF(G40>=評分方法!$C$16,"優先評估",IF(G40>=評分方法!$C$17,"列入候選",IF(G40>=評分方法!$C$18,"特定情境","不建議"))) -> 優先評估 | I40: =AE40*評分方法!$C$5 -> 30 | J40: =AF40*評分方法!$C$6 -> 10 | K40: =AG40*評分方法!$C$7 -> 15 | L40: =AH40*評分方法!$C$8 -> 15 | M40: =AI40*評分方法!$C$9 -> 2 | N40: =AJ40*評分方法!$C$10 -> 6.352 | O40: =AK40*評分方法!$C$11 -> 2.5 | P40: =AL40*評分方法!$C$12 -> 0 | Q40: 709808 | R40: 4386178 | S40: 10 億以下 | U40: 未標示, 需人工確認 | V40: safetensors;pytorch | W40: 原始開發組織 | X40: 未標示中文 | Y40: google-bert/bert-base-uncased | Z40: finetune | AA40: text-classification | AB40: 作者標示 | AC40: 授權需確認 | AD40: https://huggingface.co/GuardrailsAI/prompt-saturation-attack-detector | AE40: 1 | AF40: 1 | AG40: 1 | AH40: 1 | AI40: 0.2 | AJ40: 0.6352 | AK40: 0.5 | AL40: 0 | AM40: =COUNTIFS($D$2:$D$2501,D40,$G$2:$G$2501,">"&G40)+COUNTIFS($D$2:D40,D40,$G$2:G40,G40) -> 7 | AN40: =D40&"|"&AM40 -> AI 應用防護|7
...

Sheet 依用途前十
A1: 各資安用途類別的前十名
A2: 依「資安適用排名」分頁的類別內排名查詢; 修改權重後會自動更新. 類別依通過篩選模型中的最高分排序.
A4: 資安用途類別 | B4: 類別內排名 | C4: 模型 ID | D4: 總分 | E4: 適用等級 | F4: 建議用途
A5: AI 應用防護 | B5: 1 | C5: =IFERROR(INDEX(資安適用排名!$B$2:$B$2501,MATCH($A5&"|"&$B5,資安適用排名!$AN$2:$AN$2501,0)),"") -> protectai/deberta-v3-base-prompt-injection-v2 | D5: =IFERROR(INDEX(資安適用排名!$G$2:$G$2501,MATCH($A5&"|"&$B5,資安適用排名!$AN$2:$AN$2501,0)),"") -> 93.848 | E5: =IFERROR(INDEX(資安適用排名!$H$2:$H$2501,MATCH($A5&"|"&$B5,資安適用排名!$AN$2:$AN$2501,0)),"") -> 優先評估 | F5: =IFERROR(INDEX(資安適用排名!$E$2:$E$2501,MATCH($A5&"|"&$B5,資安適用排名!$AN$2:$AN$2501,0)),"") -> AI 應用的提示注入、越獄與有害內容偵測
A6: AI 應用防護 | B6: 2 | C6: =IFERROR(INDEX(資安適用排名!$B$2:$B$2501,MATCH($A6&"|"&$B6,資安適用排名!$AN$2:$AN$2501,0)),"") -> meta-llama/Prompt-Guard-86M | D6: =IFERROR(INDEX(資安適用排名!$G$2:$G$2501,MATCH($A6&"|"&$B6,資安適用排名!$AN$2:$AN$2501,0)),"") -> 89.792 | E6: =IFERROR(INDEX(資安適用排名!$H$2:$H$2501,MATCH($A6&"|"&$B6,資安適用排名!$AN$2:$AN$2501,0)),"") -> 優先評估 | F6: =IFERROR(INDEX(資安適用排名!$E$2:$E$2501,MATCH($A6&"|"&$B6,資安適用排名!$AN$2:$AN$2501,0)),"") -> AI 應用的提示注入、越獄與有害內容偵測
A7: AI 應用防護 | B7: 3 | C7: =IFERROR(INDEX(資安適用排名!$B$2:$B$2501,MATCH($A7&"|"&$B7,資安適用排名!$AN$2:$AN$2501,0)),"") -> protectai/deberta-v3-base-prompt-injection | D7: =IFERROR(INDEX(資安適用排名!$G$2:$G$2501,MATCH($A7&"|"&$B7,資安適用排名!$AN$2:$AN$2501,0)),"") -> 88.328 | E7: =IFERROR(INDEX(資安適用排名!$H$2:$H$2501,MATCH($A7&"|"&$B7,資安適用排名!$AN$2:$AN$2501,0)),"") -> 優先評估 | F7: =IFERROR(INDEX(資安適用排名!$E$2:$E$2501,MATCH($A7&"|"&$B7,資安適用排名!$AN$2:$AN$2501,0)),"") -> AI 應用的提示注入、越獄與有害內容偵測
A8: AI 應用防護 | B8: 4 | C8: =IFERROR(INDEX(資安適用排名!$B$2:$B$2501,MATCH($A8&"|"&$B8,資安適用排名!$AN$2:$AN$2501,0)),"") -> meta-llama/Llama-Prompt-Guard-2-86M | D8: =IFERROR(INDEX(資安適用排名!$G$2:$G$2501,MATCH($A8&"|"&$B8,資安適用排名!$AN$2:$AN$2501,0)),"") -> 84.908 | E8: =IFERROR(INDEX(資安適用排名!$H$2:$H$2501,MATCH($A8&"|"&$B8,資安適用排名!$AN$2:$AN$2501,0)),"") -> 優先評估 | F8: =IFERROR(INDEX(資安適用排名!$E$2:$E$2501,MATCH($A8&"|"&$B8,資安適用排名!$AN$2:$AN$2501,0)),"") -> AI 應用的提示注入、越獄與有害內容偵測
A9: AI 應用防護 | B9: 5 | C9: =IFERROR(INDEX(資安適用排名!$B$2:$B$2501,MATCH($A9&"|"&$B9,資安適用排名!$AN$2:$AN$2501,0)),"") -> allenai/wildguard | D9: =IFERROR(INDEX(資安適用排名!$G$2:$G$2501,MATCH($A9&"|"&$B9,資安適用排名!$AN$2:$AN$2501,0)),"") -> 83.138 | E9: =IFERROR(INDEX(資安適用排名!$H$2:$H$2501,MATCH($A9&"|"&$B9,資安適用排名!$AN$2:$AN$2501,0)),"") -> 優先評估 | F9: =IFERROR(INDEX(資安適用排名!$E$2:$E$2501,MATCH($A9&"|"&$B9,資安適用排名!$AN$2:$AN$2501,0)),"") -> AI 應用的提示注入、越獄與有害內容偵測
A10: AI 應用防護 | B10: 6 | C10: =IFERROR(INDEX(資安適用排名!$B$2:$B$2501,MATCH($A10&"|"&$B10,資安適用排名!$AN$2:$AN$2501,0)),"") -> nvidia/Nemotron-3.5-Content-Safety | D10: =IFERROR(INDEX(資安適用排名!$G$2:$G$2501,MATCH($A10&"|"&$B10,資安適用排名!$AN$2:$AN$2501,0)),"") -> 83.09 | E10: =IFERROR(INDEX(資安適用排名!$H$2:$H$2501,MATCH($A10&"|"&$B10,資安適用排名!$AN$2:$AN$2501,0)),"") -> 優先評估 | F10: =IFERROR(INDEX(資安適用排名!$E$2:$E$2501,MATCH($A10&"|"&$B10,資安適用排名!$AN$2:$AN$2501,0)),"") -> AI 應用的提示注入、越獄與有害內容偵測
A11: AI 應用防護 | B11: 7 | C11: =IFERROR(INDEX(資安適用排名!$B$2:$B$2501,MATCH($A11&"|"&$B11,資安適用排名!$AN$2:$AN$2501,0)),"") -> GuardrailsAI/prompt-saturation-attack-detector | D11: =IFERROR(INDEX(資安適用排名!$G$2:$G$2501,MATCH($A11&"|"&$B11,資安適用排名!$AN$2:$AN$2501,0)),"") -> 80.852 | E11: =IFERROR(INDEX(資安適用排名!$H$2:$H$2501,MATCH($A11&"|"&$B11,資安適用排名!$AN$2:$AN$2501,0)),"") -> 優先評估 | F11: =IFERROR(INDEX(資安適用排名!$E$2:$E$2501,MATCH($A11&"|"&$B11,資安適用排名!$AN$2:$AN$2501,0)),"") -> AI 應用的提示注入、越獄與有害內容偵測
A12: AI 應用防護 | B12: 8 | C12: =IFERROR(INDEX(資安適用排名!$B$2:$B$2501,MATCH($A12&"|"&$B12,資安適用排名!$AN$2:$AN$2501,0)),"") -> openai/gpt-oss-safeguard-20b | D12: =IFERROR(INDEX(資安適用排名!$G$2:$G$2501,MATCH($A12&"|"&$B12,資安適用排名!$AN$2:$AN$2501,0)),"") -> 80.84 | E12: =IFERROR(INDEX(資安適用排名!$H$2:$H$2501,MATCH($A12&"|"&$B12,資安適用排名!$AN$2:$AN$2501,0)),"") -> 優先評估 | F12: =IFERROR(INDEX(資安適用排名!$E$2:$E$2501,MATCH($A12&"|"&$B12,資安適用排名!$AN$2:$AN$2501,0)),"") -> AI 應用的提示注入、越獄與有害內容偵測
A13: AI 應用防護 | B13: 9 | C13: =IFERROR(INDEX(資安適用排名!$B$2:$B$2501,MATCH($A13&"|"&$B13,資安適用排名!$AN$2:$AN$2501,0)),"") -> ibm-granite/granite-guardian-4.1-8b | D13: =IFERROR(INDEX(資安適用排名!$G$2:$G$2501,MATCH($A13&"|"&$B13,資安適用排名!$AN$2:$AN$2501,0)),"") -> 80.642 | E13: =IFERROR(INDEX(資安適用排名!$H$2:$H$2501,MATCH($A13&"|"&$B13,資安適用排名!$AN$2:$AN$2501,0)),"") -> 優先評估 | F13: =IFERROR(INDEX(資安適用排名!$E$2:$E$2501,MATCH($A13&"|"&$B13,資安適用排名!$AN$2:$AN$2501,0)),"") -> AI 應用的提示注入、越獄與有害內容偵測
A14: AI 應用防護 | B14: 10 | C14: =IFERROR(INDEX(資安適用排名!$B$2:$B$2501,MATCH($A14&"|"&$B14,資安適用排名!$AN$2:$AN$2501,0)),"") -> ibm-granite/granite-guardian-3.3-8b | D14: =IFERROR(INDEX(資安適用排名!$G$2:$G$2501,MATCH($A14&"|"&$B14,資安適用排名!$AN$2:$AN$2501,0)),"") -> 78.558 | E14: =IFERROR(INDEX(資安適用排名!$H$2:$H$2501,MATCH($A14&"|"&$B14,資安適用排名!$AN$2:$AN$2501,0)),"") -> 列入候選 | F14: =IFERROR(INDEX(資安適用排名!$E$2:$E$2501,MATCH($A14&"|"&$B14,資安適用排名!$AN$2:$AN$2501,0)),"") -> AI 應用的提示注入、越獄與有害內容偵測
A15: 個資偵測與去識別化 | B15: 1 | C15: =IFERROR(INDEX(資安適用排名!$B$2:$B$2501,MATCH($A15&"|"&$B15,資安適用排名!$AN$2:$AN$2501,0)),"") -> gravitee-io/bert-small-pii-detection | D15: =IFERROR(INDEX(資安適用排名!$G$2:$G$2501,MATCH($A15&"|"&$B15,資安適用排名!$AN$2:$AN$2501,0)),"") -> 91.272 | E15: =IFERROR(INDEX(資安適用排名!$H$2:$H$2501,MATCH($A15&"|"&$B15,資安適用排名!$AN$2:$AN$2501,0)),"") -> 優先評估 | F15: =IFERROR(INDEX(資安適用排名!$E$2:$E$2501,MATCH($A15&"|"&$B15,資安適用排名!$AN$2:$AN$2501,0)),"") -> 個資偵測與遮蔽
A16: 個資偵測與去識別化 | B16: 2 | C16: =IFERROR(INDEX(資安適用排名!$B$2:$B$2501,MATCH($A16&"|"&$B16,資安適用排名!$AN$2:$AN$2501,0)),"") -> openai/privacy-filter | D16: =IFERROR(INDEX(資安適用排名!$G$2:$G$2501,MATCH($A16&"|"&$B16,資安適用排名!$AN$2:$AN$2501,0)),"") -> 90.486 | E16: =IFERROR(INDEX(資安適用排名!$H$2:$H$2501,MATCH($A16&"|"&$B16,資安適用排名!$AN$2:$AN$2501,0)),"") -> 優先評估 | F16: =IFERROR(INDEX(資安適用排名!$E$2:$E$2501,MATCH($A16&"|"&$B16,資安適用排名!$AN$2:$AN$2501,0)),"") -> 個資偵測與遮蔽
... A152: 其他 | B152: 10 | C152: =IFERROR(INDEX(資安適用排名!$B$2:$B$2501,MATCH($A152&"|"&$B152,資安適用排名!$AN$2:$AN$2501,0)),"") -> kyutai/moshiko-pytorch-bf16 | D152: =IFERROR(INDEX(資安適用排名!$G$2:$G$2501,MATCH($A152&"|"&$B152,資安適用排名!$AN$2:$AN$2501,0)),"") -> 52.486 | E152: =IFERROR(INDEX(資安適用排名!$H$2:$H$2501,MATCH($A152&"|"&$B152,資安適用排名!$AN$2:$AN$2501,0)),"") -> 不建議 | F152: =IFERROR(INDEX(資安適用排名!$E$2:$E$2501,MATCH($A152&"|"&$B152,資安適用排名!$AN$2:$AN$2501,0)),"") -> 用途有限

Sheet 排除清單
A1: 模型 ID | B1: 作者 | C1: 任務類型 | D1: 近六個月下載數 | E1: 主要排除原因 | F1: 全部不符條件 | G1: 條件代號 | H1: 模型頁面
A2: google/electra-base-discriminator | B2: google | C2: fill-mask | D2: 308762303 | E2: 只提供可執行程式碼的權重格式 (pickle 等) | F2: 只提供可執行程式碼的權重格式 (pickle 等) | G2: G3 | H2: https://huggingface.co/google/electra-base-discriminator
A3: openai/clip-vit-base-patch32 | B3: openai | C3: zero-shot-image-classification | D3: 135500974 | E3: 只提供可執行程式碼的權重格式 (pickle 等) | F3: 只提供可執行程式碼的權重格式 (pickle 等) | G3: G3 | H3: https://huggingface.co/openai/clip-vit-base-patch32
A4: nomic-ai/nomic-embed-text-v1.5 | B4: nomic-ai | C4: sentence-similarity | D4: 98440897 | E4: 需開啟 trust_remote_code | F4: 需開啟 trust_remote_code | G4: G4 | H4: https://huggingface.co/nomic-ai/nomic-embed-text-v1.5
A5: hexgrad/Kokoro-82M | B5: hexgrad | C5: text-to-speech | D5: 76160226 | E5: 只提供可執行程式碼的權重格式 (pickle 等) | F5: 只提供可執行程式碼的權重格式 (pickle 等); 生成影像、影音或語音, 無防禦用途 | G5: G3;G6 | H5: https://huggingface.co/hexgrad/Kokoro-82M
A6: Bingsu/adetailer | B6: Bingsu | D6: 71013084 | E6: 只提供可執行程式碼的權重格式 (pickle 等) | F6: 只提供可執行程式碼的權重格式 (pickle 等) | G6: G3 | H6: https://huggingface.co/Bingsu/adetailer
A7: facebook/opt-125m | B7: facebook | C7: text-generation | D7: 69907920 | E7: 只提供可執行程式碼的權重格式 (pickle 等) | F7: 只提供可執行程式碼的權重格式 (pickle 等) | G7: G3 | H7: https://huggingface.co/facebook/opt-125m
A8: argmaxinc/whisperkit-coreml | B8: argmaxinc | C8: automatic-speech-recognition | D8: 63846686 | E8: 只提供可執行程式碼的權重格式 (pickle 等) | F8: 只提供可執行程式碼的權重格式 (pickle 等) | G8: G3 | H8: https://huggingface.co/argmaxinc/whisperkit-coreml
